Workbook

Sheet Start Here
A1: Airbnb Host Business Manager
A2: Bookings · Turnovers · Occupancy & ADR · Expenses · Supplies · Profit dashboard: Google Sheets & Excel
B4: HOW TO USE
B5: 1. Settings | C5: Your business name, tax set-aside %, length-of-stay discounts, booking channels with their fee %, expense categories and cleaner names.
B6: 2. Properties | C6: One row per listing: nightly and weekend rate, cleaning fee, what you pay your cleaner, guests included and the extra-guest fee. Each row shows whether it's occupied today and the next check-in.
B7: 3. Bookings | C7: Log every reservation: property, guest, channel, check-in and check-out. Nights, rent (weekday/weekend aware), cleaning fee, platform fee, payout and your net fill in. Type the real payout from your platform in 'Actual payout' to use it instead of the estimate. Double bookings are flagged.
B8: 4. Turnovers | C8: Your cleaning schedule: every upcoming check-out, the next check-in at that property, the gap, and same-day turnover alerts. Assign the cleaner and tick Done in Bookings.
B9: 5. Expenses | C9: Mortgage or rent, utilities, repairs, supplies, software, insurance. Pick the property, or leave it blank for costs shared across all properties.
B10: 6. Supplies | C10: Par levels for toilet paper, coffee, soap and linens. Items at or below the reorder level turn red with the order quantity and cost.
B11: 7. Pricing Calculator | C11: Price any stay before you accept it (rent, fees, platform cut, cleaning cost and net per night), and find the nightly rate you need to break even.
B12: 8. Dashboard & Monthly Summary | C12: Pick a year. See payout, profit, occupancy, ADR and RevPAR per property and by month. Monthly Summary drills into one property.
B14: COLOR KEY
B15: Yellow cell, blue text | C15: Type here: your inputs
B16: White cell, black text | C16: Calculated automatically. Don't type over these.
B18: KEY TERMS
B19: Occupancy | C19: Booked nights ÷ nights available.
B20: ADR | C20: Average daily rate: rent ÷ booked nights (cleaning and other fees not included).
B21: RevPAR | C21: Rent ÷ nights available. Combines price and occupancy in one number.
B22: Payout | C22: What the platform pays you after its host fee (or the actual payout you type in).
B23: Split months | C23: A stay that crosses into a new month is split by nights, so each month gets its fair share.
B25: GOOGLE SHEETS
C26: Upload this file to Google Drive, open it, then File > Save as Google Sheets. Everything works in both Excel and Google Sheets.
C27: The example rows (marked EXAMPLE) show the format. Delete them when you start. After that, clear a booking row instead of deleting it, so Booking IDs stay the same.
C28: Default fees and rates are examples. Check your own platform fees. Expense categories are an organizing aid, not tax advice. Not affiliated with or endorsed by Airbnb, Inc. or Vrbo.

Sheet Dashboard
A1: Dashboard
A2: Pick a year. Everything updates from Properties, Bookings and Expenses.
A4: Year | B4: 2026 | D4: All properties
A6: Payout | C6: Profit | E6: Occupancy | F6: ADR (avg nightly rate) | H6: Unpaid direct bookings | I6: Tax set-aside
A7: =F22 -> 1241.6 | C7: =I22 -> 949.43 | E7: =C22 -> 0.01369863 | F7: =D22 -> 201 | H7: =SUMIFS(Bookings!$Q$5:$Q$1004,Bookings!$U$5:$U$1004,"No",Bookings!$AA$5:$AA$1004,1) -> 582 | I7: =MAX(0,I22)*Settings!$B$8 -> 237.3575
A9: Month | B9: Nights booked | C9: Occupancy | D9: ADR | E9: RevPAR | F9: Payout | G9: Cleaning costs | H9: Expenses | I9: Profit | K9: Nights available | L9: Rent
A10: =TEXT(DATE($B$4,1,1),"mmm yyyy") -> Jan 2026 | B10: =SUMPRODUCT(Bookings!$AA$5:$AA$1004*(($D$4="All properties")+(Bookings!$D$5:$D$1004=$D$4)>0)*(((((Bookings!$C$5:$C$1004+DATE($B$4,2,1)-ABS(Bookings!$C$5:$C$1004-DATE($B$4,2,1)))/2)-((Bookings!$B$5:$B$1004+DATE($B$4,1,1)+ABS(Bookings!$B$5:$B$1004-DATE($B$4,1,1)))/2))+ABS(((Bookings!$C$5:$C$1004+DATE($B$4,2,1)-ABS(Bookings!$C$5:$C$1004-DATE($B$4,2,1)))/2)-((Bookings!$B$5:$B$1004+DATE($B$4,1,1)+ABS(Bookings!$B$5:$B$1004-DATE($B$4,1,1)))/2)))/2)) -> 0 | C10: =IF(K10=0,0,B10/K10) -> 0 | D10: =IF(B10=0,0,L10/B10) -> 0 | E10: =IF(K10=0,0,L10/K10) -> 0 | F10: =SUMPRODUCT(Bookings!$AA$5:$AA$1004*(($D$4="All properties")+(Bookings!$D$5:$D$1004=$D$4)>0)*(((((Bookings!$C$5:$C$1004+DATE($B$4,2,1)-ABS(Bookings!$C$5:$C$1004-DATE($B$4,2,1)))/2)-((Bookings!$B$5:$B$1004+DATE($B$4,1,1)+ABS(Bookings!$B$5:$B$1004-DATE($B$4,1,1)))/2))+ABS(((Bookings!$C$5:$C$1004+DATE($B$4,2,1)-ABS(Bookings!$C$5:$C$1004-DATE($B$4,2,1)))/2)-((Bookings!$B$5:$B$1004+DATE($B$4,1,1)+ABS(Bookings!$B$5:$B$1004-DATE($B$4,1,1)))/2)))/2)*Bookings!$AC$5:$AC$1004) -> 0 | G10: =SUMPRODUCT(Bookings!$AA$5:$AA$1004*(($D$4="All properties")+(Bookings!$D$5:$D$1004=$D$4)>0)*(((((Bookings!$C$5:$C$1004+DATE($B$4,2,1)-ABS(Bookings!$C$5:$C$1004-DATE($B$4,2,1)))/2)-((Bookings!$B$5:$B$1004+DATE($B$4,1,1)+ABS(Bookings!$B$5:$B$1004-DATE($B$4,1,1)))/2))+ABS(((Bookings!$C$5:$C$1004+DATE($B$4,2,1)-ABS(Bookings!$C$5:$C$1004-DATE($B$4,2,1)))/2)-((Bookings!$B$5:$B$1004+DATE($B$4,1,1)+ABS(Bookings!$B$5:$B$1004-DATE($B$4,1,1)))/2)))/2)*Bookings!$AD$5:$AD$1004) -> 0 | H10: =IF($D$4="All properties",SUMIFS(Expenses!$F$5:$F$1004,Expenses!$A$5:$A$1004,">="&DATE($B$4,1,1),Expenses!$A$5:$A$1004,"<"&DATE($B$4,2,1)),SUMIFS(Expenses!$F$5:$F$1004,Expenses!$A$5:$A$1004,">="&DATE($B$4,1,1),Expenses!$A$5:$A$1004,"<"&DATE($B$4,2,1),Expenses!$B$5:$B$1004,$D$4)) -> 0 | I10: =F10-G10-H10 -> 0 | K10: =SUMPRODUCT((Properties!$A$5:$A$24<>"")*(($D$4="All properties")+(Properties!$A$5:$A$24=$D$4)>0)*(((DATE($B$4,2,1)-((Properties!$K$5:$K$24+DATE($B$4,1,1)+ABS(Properties!$K$5:$K$24-DATE($B$4,1,1)))/2))+ABS(DATE($B$4,2,1)-((Properties!$K$5:$K$24+DATE($B$4,1,1)+ABS(Properties!$K$5:$K$24-DATE($B$4,1,1)))/2)))/2)) -> 31 | L10: =SUMPRODUCT(Bookings!$AA$5:$AA$1004*(($D$4="All properties")+(Bookings!$D$5:$D$1004=$D$4)>0)*(((((Bookings!$C$5:$C$1004+DATE($B$4,2,1)-ABS(Bookings!$C$5:$C$1004-DATE($B$4,2,1)))/2)-((Bookings!$B$5:$B$1004+DATE($B$4,1,1)+ABS(Bookings!$B$5:$B$1004-DATE($B$4,1,1)))/2))+ABS(((Bookings!$C$5:$C$1004+DATE($B$4,2,1)-ABS(Bookings!$C$5:$C$1004-DATE($B$4,2,1)))/2)-((Bookings!$B$5:$B$1004+DATE($B$4,1,1)+ABS(Bookings!$B$5:$B$1004-DATE($B$4,1,1)))/2)))/2)*Bookings!$AB$5:$AB$1004) -> 0
A11: =TEXT(DATE($B$4,2,1),"mmm yyyy") -> Feb 2026 | B11: =SUMPRODUCT(Bookings!$AA$5:$AA$1004*(($D$4="All properties")+(Bookings!$D$5:$D$1004=$D$4)>0)*(((((Bookings!$C$5:$C$1004+DATE($B$4,3,1)-ABS(Bookings!$C$5:$C$1004-DATE($B$4,3,1)))/2)-((Bookings!$B$5:$B$1004+DATE($B$4,2,1)+ABS(Bookings!$B$5:$B$1004-DATE($B$4,2,1)))/2))+ABS(((Bookings!$C$5:$C$1004+DATE($B$4,3,1)-ABS(Bookings!$C$5:$C$1004-DATE($B$4,3,1)))/2)-((Bookings!$B$5:$B$1004+DATE($B$4,2,1)+ABS(Bookings!$B$5:$B$1004-DATE($B$4,2,1)))/2)))/2)) -> 0 | C11: =IF(K11=0,0,B11/K11) -> 0 | D11: =IF(B11=0,0,L11/B11) -> 0 | E11: =IF(K11=0,0,L11/K11) -> 0 | F11: =SUMPRODUCT(Bookings!$AA$5:$AA$1004*(($D$4="All properties")+(Bookings!$D$5:$D$1004=$D$4)>0)*(((((Bookings!$C$5:$C$1004+DATE($B$4,3,1)-ABS(Bookings!$C$5:$C$1004-DATE($B$4,3,1)))/2)-((Bookings!$B$5:$B$1004+DATE($B$4,2,1)+ABS(Bookings!$B$5:$B$1004-DATE($B$4,2,1)))/2))+ABS(((Bookings!$C$5:$C$1004+DATE($B$4,3,1)-ABS(Bookings!$C$5:$C$1004-DATE($B$4,3,1)))/2)-((Bookings!$B$5:$B$1004+DATE($B$4,2,1)+ABS(Bookings!$B$5:$B$1004-DATE($B$4,2,1)))/2)))/2)*Bookings!$AC$5:$AC$1004) -> 0 | G11: =SUMPRODUCT(Bookings!$AA$5:$AA$1004*(($D$4="All properties")+(Bookings!$D$5:$D$1004=$D$4)>0)*(((((Bookings!$C$5:$C$1004+DATE($B$4,3,1)-ABS(Bookings!$C$5:$C$1004-DATE($B$4,3,1)))/2)-((Bookings!$B$5:$B$1004+DATE($B$4,2,1)+ABS(Bookings!$B$5:$B$1004-DATE($B$4,2,1)))/2))+ABS(((Bookings!$C$5:$C$1004+DATE($B$4,3,1)-ABS(Bookings!$C$5:$C$1004-DATE($B$4,3,1)))/2)-((Bookings!$B$5:$B$1004+DATE($B$4,2,1)+ABS(Bookings!$B$5:$B$1004-DATE($B$4,2,1)))/2)))/2)*Bookings!$AD$5:$AD$1004) -> 0 | H11: =IF($D$4="All properties",SUMIFS(Expenses!$F$5:$F$1004,Expenses!$A$5:$A$1004,">="&DATE($B$4,2,1),Expenses!$A$5:$A$1004,"<"&DATE($B$4,3,1)),SUMIFS(Expenses!$F$5:$F$1004,Expenses!$A$5:$A$1004,">="&DATE($B$4,2,1),Expenses!$A$5:$A$1004,"<"&DATE($B$4,3,1),Expenses!$B$5:$B$1004,$D$4)) -> 0 | I11: =F11-G11-H11 -> 0 | K11: =SUMPRODUCT((Properties!$A$5:$A$24<>"")*(($D$4="All properties")+(Properties!$A$5:$A$24=$D$4)>0)*(((DATE($B$4,3,1)-((Properties!$K$5:$K$24+DATE($B$4,2,1)+ABS(Properties!$K$5:$K$24-DATE($B$4,2,1)))/2))+ABS(DATE($B$4,3,1)-((Properties!$K$5:$K$24+DATE($B$4,2,1)+ABS(Properties!$K$5:$K$24-DATE($B$4,2,1)))/2)))/2)) -> 28 | L11: =SUMPRODUCT(Bookings!$AA$5:$AA$1004*(($D$4="All properties")+(Bookings!$D$5:$D$1004=$D$4)>0)*(((((Bookings!$C$5:$C$1004+DATE($B$4,3,1)-ABS(Bookings!$C$5:$C$1004-DATE($B$4,3,1)))/2)-((Bookings!$B$5:$B$1004+DATE($B$4,2,1)+ABS(Bookings!$B$5:$B$1004-DATE($B$4,2,1)))/2))+ABS(((Bookings!$C$5:$C$1004+DATE($B$4,3,1)-ABS(Bookings!$C$5:$C$1004-DATE($B$4,3,1)))/2)-((Bookings!$B$5:$B$1004+DATE($B$4,2,1)+ABS(Bookings!$B$5:$B$1004-DATE($B$4,2,1)))/2)))/2)*Bookings!$AB$5:$AB$1004) -> 0
A12: =TEXT(DATE($B$4,3,1),"mmm yyyy") -> Mar 2026 | B12: =SUMPRODUCT(Bookings!$AA$5:$AA$1004*(($D$4="All properties")+(Bookings!$D$5:$D$1004=$D$4)>0)*(((((Bookings!$C$5:$C$1004+DATE($B$4,4,1)-ABS(Bookings!$C$5:$C$1004-DATE($B$4,4,1)))/2)-((Bookings!$B$5:$B$1004+DATE($B$4,3,1)+ABS(Bookings!$B$5:$B$1004-DATE($B$4,3,1)))/2))+ABS(((Bookings!$C$5:$C$1004+DATE($B$4,4,1)-ABS(Bookings!$C$5:$C$1004-DATE($B$4,4,1)))/2)-((Bookings!$B$5:$B$1004+DATE($B$4,3,1)+ABS(Bookings!$B$5:$B$1004-DATE($B$4,3,1)))/2)))/2)) -> 0 | C12: =IF(K12=0,0,B12/K12) -> 0 | D12: =IF(B12=0,0,L12/B12) -> 0 | E12: =IF(K12=0,0,L12/K12) -> 0 | F12: =SUMPRODUCT(Bookings!$AA$5:$AA$1004*(($D$4="All properties")+(Bookings!$D$5:$D$1004=$D$4)>0)*(((((Bookings!$C$5:$C$1004+DATE($B$4,4,1)-ABS(Bookings!$C$5:$C$1004-DATE($B$4,4,1)))/2)-((Bookings!$B$5:$B$1004+DATE($B$4,3,1)+ABS(Bookings!$B$5:$B$1004-DATE($B$4,3,1)))/2))+ABS(((Bookings!$C$5:$C$1004+DATE($B$4,4,1)-ABS(Bookings!$C$5:$C$1004-DATE($B$4,4,1)))/2)-((Bookings!$B$5:$B$1004+DATE($B$4,3,1)+ABS(Bookings!$B$5:$B$1004-DATE($B$4,3,1)))/2)))/2)*Bookings!$AC$5:$AC$1004) -> 0 | G12: =SUMPRODUCT(Bookings!$AA$5:$AA$1004*(($D$4="All properties")+(Bookings!$D$5:$D$1004=$D$4)>0)*(((((Bookings!$C$5:$C$1004+DATE($B$4,4,1)-ABS(Bookings!$C$5:$C$1004-DATE($B$4,4,1)))/2)-((Bookings!$B$5:$B$1004+DATE($B$4,3,1)+ABS(Bookings!$B$5:$B$1004-DATE($B$4,3,1)))/2))+ABS(((Bookings!$C$5:$C$1004+DATE($B$4,4,1)-ABS(Bookings!$C$5:$C$1004-DATE($B$4,4,1)))/2)-((Bookings!$B$5:$B$1004+DATE($B$4,3,1)+ABS(Bookings!$B$5:$B$1004-DATE($B$4,3,1)))/2)))/2)*Bookings!$AD$5:$AD$1004) -> 0 | H12: =IF($D$4="All properties",SUMIFS(Expenses!$F$5:$F$1004,Expenses!$A$5:$A$1004,">="&DATE($B$4,3,1),Expenses!$A$5:$A$1004,"<"&DATE($B$4,4,1)),SUMIFS(Expenses!$F$5:$F$1004,Expenses!$A$5:$A$1004,">="&DATE($B$4,3,1),Expenses!$A$5:$A$1004,"<"&DATE($B$4,4,1),Expenses!$B$5:$B$1004,$D$4)) -> 0 | I12: =F12-G12-H12 -> 0 | K12: =SUMPRODUCT((Properties!$A$5:$A$24<>"")*(($D$4="All properties")+(Properties!$A$5:$A$24=$D$4)>0)*(((DATE($B$4,4,1)-((Properties!$K$5:$K$24+DATE($B$4,3,1)+ABS(Properties!$K$5:$K$24-DATE($B$4,3,1)))/2))+ABS(DATE($B$4,4,1)-((Properties!$K$5:$K$24+DATE($B$4,3,1)+ABS(Properties!$K$5:$K$24-DATE($B$4,3,1)))/2)))/2)) -> 31 | L12: =SUMPRODUCT(Bookings!$AA$5:$AA$1004*(($D$4="All properties")+(Bookings!$D$5:$D$1004=$D$4)>0)*(((((Bookings!$C$5:$C$1004+DATE($B$4,4,1)-ABS(Bookings!$C$5:$C$1004-DATE($B$4,4,1)))/2)-((Bookings!$B$5:$B$1004+DATE($B$4,3,1)+ABS(Bookings!$B$5:$B$1004-DATE($B$4,3,1)))/2))+ABS(((Bookings!$C$5:$C$1004+DATE($B$4,4,1)-ABS(Bookings!$C$5:$C$1004-DATE($B$4,4,1)))/2)-((Bookings!$B$5:$B$1004+DATE($B$4,3,1)+ABS(Bookings!$B$5:$B$1004-DATE($B$4,3,1)))/2)))/2)*Bookings!$AB$5:$AB$1004) -> 0
A13: =TEXT(DATE($B$4,4,1),"mmm yyyy") -> Apr 2026 | B13: =SUMPRODUCT(Bookings!$AA$5:$AA$1004*(($D$4="All properties")+(Bookings!$D$5:$D$1004=$D$4)>0)*(((((Bookings!$C$5:$C$1004+DATE($B$4,5,1)-ABS(Bookings!$C$5:$C$1004-DATE($B$4,5,1)))/2)-((Bookings!$B$5:$B$1004+DATE($B$4,4,1)+ABS(Bookings!$B$5:$B$1004-DATE($B$4,4,1)))/2))+ABS(((Bookings!$C$5:$C$1004+DATE($B$4,5,1)-ABS(Bookings!$C$5:$C$1004-DATE($B$4,5,1)))/2)-((Bookings!$B$5:$B$1004+DATE($B$4,4,1)+ABS(Bookings!$B$5:$B$1004-DATE($B$4,4,1)))/2)))/2)) -> 0 | C13: =IF(K13=0,0,B13/K13) -> 0 | D13: =IF(B13=0,0,L13/B13) -> 0 | E13: =IF(K13=0,0,L13/K13) -> 0 | F13: =SUMPRODUCT(Bookings!$AA$5:$AA$1004*(($D$4="All properties")+(Bookings!$D$5:$D$1004=$D$4)>0)*(((((Bookings!$C$5:$C$1004+DATE($B$4,5,1)-ABS(Bookings!$C$5:$C$1004-DATE($B$4,5,1)))/2)-((Bookings!$B$5:$B$1004+DATE($B$4,4,1)+ABS(Bookings!$B$5:$B$1004-DATE($B$4,4,1)))/2))+ABS(((Bookings!$C$5:$C$1004+DATE($B$4,5,1)-ABS(Bookings!$C$5:$C$1004-DATE($B$4,5,1)))/2)-((Bookings!$B$5:$B$1004+DATE($B$4,4,1)+ABS(Bookings!$B$5:$B$1004-DATE($B$4,4,1)))/2)))/2)*Bookings!$AC$5:$AC$1004) -> 0 | G13: =SUMPRODUCT(Bookings!$AA$5:$AA$1004*(($D$4="All properties")+(Bookings!$D$5:$D$1004=$D$4)>0)*(((((Bookings!$C$5:$C$1004+DATE($B$4,5,1)-ABS(Bookings!$C$5:$C$1004-DATE($B$4,5,1)))/2)-((Bookings!$B$5:$B$1004+DATE($B$4,4,1)+ABS(Bookings!$B$5:$B$1004-DATE($B$4,4,1)))/2))+ABS(((Bookings!$C$5:$C$1004+DATE($B$4,5,1)-ABS(Bookings!$C$5:$C$1004-DATE($B$4,5,1)))/2)-((Bookings!$B$5:$B$1004+DATE($B$4,4,1)+ABS(Bookings!$B$5:$B$1004-DATE($B$4,4,1)))/2)))/2)*Bookings!$AD$5:$AD$1004) -> 0 | H13: =IF($D$4="All properties",SUMIFS(Expenses!$F$5:$F$1004,Expenses!$A$5:$A$1004,">="&DATE($B$4,4,1),Expenses!$A$5:$A$1004,"<"&DATE($B$4,5,1)),SUMIFS(Expenses!$F$5:$F$1004,Expenses!$A$5:$A$1004,">="&DATE($B$4,4,1),Expenses!$A$5:$A$1004,"<"&DATE($B$4,5,1),Expenses!$B$5:$B$1004,$D$4)) -> 0 | I13: =F13-G13-H13 -> 0 | K13: =SUMPRODUCT((Properties!$A$5:$A$24<>"")*(($D$4="All properties")+(Properties!$A$5:$A$24=$D$4)>0)*(((DATE($B$4,5,1)-((Properties!$K$5:$K$24+DATE($B$4,4,1)+ABS(Properties!$K$5:$K$24-DATE($B$4,4,1)))/2))+ABS(DATE($B$4,5,1)-((Properties!$K$5:$K$24+DATE($B$4,4,1)+ABS(Properties!$K$5:$K$24-DATE($B$4,4,1)))/2)))/2)) -> 30 | L13: =SUMPRODUCT(Bookings!$AA$5:$AA$1004*(($D$4="All properties")+(Bookings!$D$5:$D$1004=$D$4)>0)*(((((Bookings!$C$5:$C$1004+DATE($B$4,5,1)-ABS(Bookings!$C$5:$C$1004-DATE($B$4,5,1)))/2)-((Bookings!$B$5:$B$1004+DATE($B$4,4,1)+ABS(Bookings!$B$5:$B$1004-DATE($B$4,4,1)))/2))+ABS(((Bookings!$C$5:$C$1004+DATE($B$4,5,1)-ABS(Bookings!$C$5:$C$1004-DATE($B$4,5,1)))/2)-((Bookings!$B$5:$B$1004+DATE($B$4,4,1)+ABS(Bookings!$B$5:$B$1004-DATE($B$4,4,1)))/2)))/2)*Bookings!$AB$5:$AB$1004) -> 0
A14: =TEXT(DATE($B$4,5,1),"mmm yyyy") -> May 2026 | B14: =SUMPRODUCT(Bookings!$AA$5:$AA$1004*(($D$4="All properties")+(Bookings!$D$5:$D$1004=$D$4)>0)*(((((Bookings!$C$5:$C$1004+DATE($B$4,6,1)-ABS(Bookings!$C$5:$C$1004-DATE($B$4,6,1)))/2)-((Bookings!$B$5:$B$1004+DATE($B$4,5,1)+ABS(Bookings!$B$5:$B$1004-DATE($B$4,5,1)))/2))+ABS(((Bookings!$C$5:$C$1004+DATE($B$4,6,1)-ABS(Bookings!$C$5:$C$1004-DATE($B$4,6,1)))/2)-((Bookings!$B$5:$B$1004+DATE($B$4,5,1)+ABS(Bookings!$B$5:$B$1004-DATE($B$4,5,1)))/2)))/2)) -> 0 | C14: =IF(K14=0,0,B14/K14) -> 0 | D14: =IF(B14=0,0,L14/B14) -> 0 | E14: =IF(K14=0,0,L14/K14) -> 0 | F14: =SUMPRODUCT(Bookings!$AA$5:$AA$1004*(($D$4="All properties")+(Bookings!$D$5:$D$1004=$D$4)>0)*(((((Bookings!$C$5:$C$1004+DATE($B$4,6,1)-ABS(Bookings!$C$5:$C$1004-DATE($B$4,6,1)))/2)-((Bookings!$B$5:$B$1004+DATE($B$4,5,1)+ABS(Bookings!$B$5:$B$1004-DATE($B$4,5,1)))/2))+ABS(((Bookings!$C$5:$C$1004+DATE($B$4,6,1)-ABS(Bookings!$C$5:$C$1004-DATE($B$4,6,1)))/2)-((Bookings!$B$5:$B$1004+DATE($B$4,5,1)+ABS(Bookings!$B$5:$B$1004-DATE($B$4,5,1)))/2)))/2)*Bookings!$AC$5:$AC$1004) -> 0 | G14: =SUMPRODUCT(Bookings!$AA$5:$AA$1004*(($D$4="All properties")+(Bookings!$D$5:$D$1004=$D$4)>0)*(((((Bookings!$C$5:$C$1004+DATE($B$4,6,1)-ABS(Bookings!$C$5:$C$1004-DATE($B$4,6,1)))/2)-((Bookings!$B$5:$B$1004+DATE($B$4,5,1)+ABS(Bookings!$B$5:$B$1004-DATE($B$4,5,1)))/2))+ABS(((Bookings!$C$5:$C$1004+DATE($B$4,6,1)-ABS(Bookings!$C$5:$C$1004-DATE($B$4,6,1)))/2)-((Bookings!$B$5:$B$1004+DATE($B$4,5,1)+ABS(Bookings!$B$5:$B$1004-DATE($B$4,5,1)))/2)))/2)*Bookings!$AD$5:$AD$1004) -> 0 | H14: =IF($D$4="All properties",SUMIFS(Expenses!$F$5:$F$1004,Expenses!$A$5:$A$1004,">="&DATE($B$4,5,1),Expenses!$A$5:$A$1004,"<"&DATE($B$4,6,1)),SUMIFS(Expenses!$F$5:$F$1004,Expenses!$A$5:$A$1004,">="&DATE($B$4,5,1),Expenses!$A$5:$A$1004,"<"&DATE($B$4,6,1),Expenses!$B$5:$B$1004,$D$4)) -> 0 | I14: =F14-G14-H14 -> 0 | K14: =SUMPRODUCT((Properties!$A$5:$A$24<>"")*(($D$4="All properties")+(Properties!$A$5:$A$24=$D$4)>0)*(((DATE($B$4,6,1)-((Properties!$K$5:$K$24+DATE($B$4,5,1)+ABS(Properties!$K$5:$K$24-DATE($B$4,5,1)))/2))+ABS(DATE($B$4,6,1)-((Properties!$K$5:$K$24+DATE($B$4,5,1)+ABS(Properties!$K$5:$K$24-DATE($B$4,5,1)))/2)))/2)) -> 31 | L14: =SUMPRODUCT(Bookings!$AA$5:$AA$1004*(($D$4="All properties")+(Bookings!$D$5:$D$1004=$D$4)>0)*(((((Bookings!$C$5:$C$1004+DATE($B$4,6,1)-ABS(Bookings!$C$5:$C$1004-DATE($B$4,6,1)))/2)-((Bookings!$B$5:$B$1004+DATE($B$4,5,1)+ABS(Bookings!$B$5:$B$1004-DATE($B$4,5,1)))/2))+ABS(((Bookings!$C$5:$C$1004+DATE($B$4,6,1)-ABS(Bookings!$C$5:$C$1004-DATE($B$4,6,1)))/2)-((Bookings!$B$5:$B$1004+DATE($B$4,5,1)+ABS(Bookings!$B$5:$B$1004-DATE($B$4,5,1)))/2)))/2)*Bookings!$AB$5:$AB$1004) -> 0
A15: =TEXT(DATE($B$4,6,1),"mmm yyyy") -> Jun 2026 | B15: =SUMPRODUCT(Bookings!$AA$5:$AA$1004*(($D$4="All properties")+(Bookings!$D$5:$D$1004=$D$4)>0)*(((((Bookings!$C$5:$C$1004+DATE($B$4,7,1)-ABS(Bookings!$C$5:$C$1004-DATE($B$4,7,1)))/2)-((Bookings!$B$5:$B$1004+DATE($B$4,6,1)+ABS(Bookings!$B$5:$B$1004-DATE($B$4,6,1)))/2))+ABS(((Bookings!$C$5:$C$1004+DATE($B$4,7,1)-ABS(Bookings!$C$5:$C$1004-DATE($B$4,7,1)))/2)-((Bookings!$B$5:$B$1004+DATE($B$4,6,1)+ABS(Bookings!$B$5:$B$1004-DATE($B$4,6,1)))/2)))/2)) -> 0 | C15: =IF(K15=0,0,B15/K15) -> 0 | D15: =IF(B15=0,0,L15/B15) -> 0 | E15: =IF(K15=0,0,L15/K15) -> 0 | F15: =SUMPRODUCT(Bookings!$AA$5:$AA$1004*(($D$4="All properties")+(Bookings!$D$5:$D$1004=$D$4)>0)*(((((Bookings!$C$5:$C$1004+DATE($B$4,7,1)-ABS(Bookings!$C$5:$C$1004-DATE($B$4,7,1)))/2)-((Bookings!$B$5:$B$1004+DATE($B$4,6,1)+ABS(Bookings!$B$5:$B$1004-DATE($B$4,6,1)))/2))+ABS(((Bookings!$C$5:$C$1004+DATE($B$4,7,1)-ABS(Bookings!$C$5:$C$1004-DATE($B$4,7,1)))/2)-((Bookings!$B$5:$B$1004+DATE($B$4,6,1)+ABS(Bookings!$B$5:$B$1004-DATE($B$4,6,1)))/2)))/2)*Bookings!$AC$5:$AC$1004) -> 0 | G15: =SUMPRODUCT(Bookings!$AA$5:$AA$1004*(($D$4="All properties")+(Bookings!$D$5:$D$1004=$D$4)>0)*(((((Bookings!$C$5:$C$1004+DATE($B$4,7,1)-ABS(Bookings!$C$5:$C$1004-DATE($B$4,7,1)))/2)-((Bookings!$B$5:$B$1004+DATE($B$4,6,1)+ABS(Bookings!$B$5:$B$1004-DATE($B$4,6,1)))/2))+ABS(((Bookings!$C$5:$C$1004+DATE($B$4,7,1)-ABS(Bookings!$C$5:$C$1004-DATE($B$4,7,1)))/2)-((Bookings!$B$5:$B$1004+DATE($B$4,6,1)+ABS(Bookings!$B$5:$B$1004-DATE($B$4,6,1)))/2)))/2)*Bookings!$AD$5:$AD$1004) -> 0 | H15: =IF($D$4="All properties",SUMIFS(Expenses!$F$5:$F$1004,Expenses!$A$5:$A$1004,">="&DATE($B$4,6,1),Expenses!$A$5:$A$1004,"<"&DATE($B$4,7,1)),SUMIFS(Expenses!$F$5:$F$1004,Expenses!$A$5:$A$1004,">="&DATE($B$4,6,1),Expenses!$A$5:$A$1004,"<"&DATE($B$4,7,1),Expenses!$B$5:$B$1004,$D$4)) -> 0 | I15: =F15-G15-H15 -> 0 | K15: =SUMPRODUCT((Properties!$A$5:$A$24<>"")*(($D$4="All properties")+(Properties!$A$5:$A$24=$D$4)>0)*(((DATE($B$4,7,1)-((Properties!$K$5:$K$24+DATE($B$4,6,1)+ABS(Properties!$K$5:$K$24-DATE($B$4,6,1)))/2))+ABS(DATE($B$4,7,1)-((Properties!$K$5:$K$24+DATE($B$4,6,1)+ABS(Properties!$K$5:$K$24-DATE($B$4,6,1)))/2)))/2)) -> 30 | L15: =SUMPRODUCT(Bookings!$AA$5:$AA$1004*(($D$4="All properties")+(Bookings!$D$5:$D$1004=$D$4)>0)*(((((Bookings!$C$5:$C$1004+DATE($B$4,7,1)-ABS(Bookings!$C$5:$C$1004-DATE($B$4,7,1)))/2)-((Bookings!$B$5:$B$1004+DATE($B$4,6,1)+ABS(Bookings!$B$5:$B$1004-DATE($B$4,6,1)))/2))+ABS(((Bookings!$C$5:$C$1004+DATE($B$4,7,1)-ABS(Bookings!$C$5:$C$1004-DATE($B$4,7,1)))/2)-((Bookings!$B$5:$B$1004+DATE($B$4,6,1)+ABS(Bookings!$B$5:$B$1004-DATE($B$4,6,1)))/2)))/2)*Bookings!$AB$5:$AB$1004) -> 0
A16: =TEXT(DATE($B$4,7,1),"mmm yyyy") -> Jul 2026 | B16: =SUMPRODUCT(Bookings!$AA$5:$AA$1004*(($D$4="All properties")+(Bookings!$D$5:$D$1004=$D$4)>0)*(((((Bookings!$C$5:$C$1004+DATE($B$4,8,1)-ABS(Bookings!$C$5:$C$1004-DATE($B$4,8,1)))/2)-((Bookings!$B$5:$B$1004+DATE($B$4,7,1)+ABS(Bookings!$B$5:$B$1004-DATE($B$4,7,1)))/2))+ABS(((Bookings!$C$5:$C$1004+DATE($B$4,8,1)-ABS(Bookings!$C$5:$C$1004-DATE($B$4,8,1)))/2)-((Bookings!$B$5:$B$1004+DATE($B$4,7,1)+ABS(Bookings!$B$5:$B$1004-DATE($B$4,7,1)))/2)))/2)) -> 0 | C16: =IF(K16=0,0,B16/K16) -> 0 | D16: =IF(B16=0,0,L16/B16) -> 0 | E16: =IF(K16=0,0,L16/K16) -> 0 | F16: =SUMPRODUCT(Bookings!$AA$5:$AA$1004*(($D$4="All properties")+(Bookings!$D$5:$D$1004=$D$4)>0)*(((((Bookings!$C$5:$C$1004+DATE($B$4,8,1)-ABS(Bookings!$C$5:$C$1004-DATE($B$4,8,1)))/2)-((Bookings!$B$5:$B$1004+DATE($B$4,7,1)+ABS(Bookings!$B$5:$B$1004-DATE($B$4,7,1)))/2))+ABS(((Bookings!$C$5:$C$1004+DATE($B$4,8,1)-ABS(Bookings!$C$5:$C$1004-DATE($B$4,8,1)))/2)-((Bookings!$B$5:$B$1004+DATE($B$4,7,1)+ABS(Bookings!$B$5:$B$1004-DATE($B$4,7,1)))/2)))/2)*Bookings!$AC$5:$AC$1004) -> 0 | G16: =SUMPRODUCT(Bookings!$AA$5:$AA$1004*(($D$4="All properties")+(Bookings!$D$5:$D$1004=$D$4)>0)*(((((Bookings!$C$5:$C$1004+DATE($B$4,8,1)-ABS(Bookings!$C$5:$C$1004-DATE($B$4,8,1)))/2)-((Bookings!$B$5:$B$1004+DATE($B$4,7,1)+ABS(Bookings!$B$5:$B$1004-DATE($B$4,7,1)))/2))+ABS(((Bookings!$C$5:$C$1004+DATE($B$4,8,1)-ABS(Bookings!$C$5:$C$1004-DATE($B$4,8,1)))/2)-((Bookings!$B$5:$B$1004+DATE($B$4,7,1)+ABS(Bookings!$B$5:$B$1004-DATE($B$4,7,1)))/2)))/2)*Bookings!$AD$5:$AD$1004) -> 0 | H16: =IF($D$4="All properties",SUMIFS(Expenses!$F$5:$F$1004,Expenses!$A$5:$A$1004,">="&DATE($B$4,7,1),Expenses!$A$5:$A$1004,"<"&DATE($B$4,8,1)),SUMIFS(Expenses!$F$5:$F$1004,Expenses!$A$5:$A$1004,">="&DATE($B$4,7,1),Expenses!$A$5:$A$1004,"<"&DATE($B$4,8,1),Expenses!$B$5:$B$1004,$D$4)) -> 0 | I16: =F16-G16-H16 -> 0 | K16: =SUMPRODUCT((Properties!$A$5:$A$24<>"")*(($D$4="All properties")+(Properties!$A$5:$A$24=$D$4)>0)*(((DATE($B$4,8,1)-((Properties!$K$5:$K$24+DATE($B$4,7,1)+ABS(Properties!$K$5:$K$24-DATE($B$4,7,1)))/2))+ABS(DATE($B$4,8,1)-((Properties!$K$5:$K$24+DATE($B$4,7,1)+ABS(Properties!$K$5:$K$24-DATE($B$4,7,1)))/2)))/2)) -> 31 | L16: =SUMPRODUCT(Bookings!$AA$5:$AA$1004*(($D$4="All properties")+(Bookings!$D$5:$D$1004=$D$4)>0)*(((((Bookings!$C$5:$C$1004+DATE($B$4,8,1)-ABS(Bookings!$C$5:$C$1004-DATE($B$4,8,1)))/2)-((Bookings!$B$5:$B$1004+DATE($B$4,7,1)+ABS(Bookings!$B$5:$B$1004-DATE($B$4,7,1)))/2))+ABS(((Bookings!$C$5:$C$1004+DATE($B$4,8,1)-ABS(Bookings!$C$5:$C$1004-DATE($B$4,8,1)))/2)-((Bookings!$B$5:$B$1004+DATE($B$4,7,1)+ABS(Bookings!$B$5:$B$1004-DATE($B$4,7,1)))/2)))/2)*Bookings!$AB$5:$AB$1004) -> 0
A17: =TEXT(DATE($B$4,8,1),"mmm yyyy") -> Aug 2026 | B17: =SUMPRODUCT(Bookings!$AA$5:$AA$1004*(($D$4="All properties")+(Bookings!$D$5:$D$1004=$D$4)>0)*(((((Bookings!$C$5:$C$1004+DATE($B$4,9,1)-ABS(Bookings!$C$5:$C$1004-DATE($B$4,9,1)))/2)-((Bookings!$B$5:$B$1004+DATE($B$4,8,1)+ABS(Bookings!$B$5:$B$1004-DATE($B$4,8,1)))/2))+ABS(((Bookings!$C$5:$C$1004+DATE($B$4,9,1)-ABS(Bookings!$C$5:$C$1004-DATE($B$4,9,1)))/2)-((Bookings!$B$5:$B$1004+DATE($B$4,8,1)+ABS(Bookings!$B$5:$B$1004-DATE($B$4,8,1)))/2)))/2)) -> 0 | C17: =IF(K17=0,0,B17/K17) -> 0 | D17: =IF(B17=0,0,L17/B17) -> 0 | E17: =IF(K17=0,0,L17/K17) -> 0 | F17: =SUMPRODUCT(Bookings!$AA$5:$AA$1004*(($D$4="All properties")+(Bookings!$D$5:$D$1004=$D$4)>0)*(((((Bookings!$C$5:$C$1004+DATE($B$4,9,1)-ABS(Bookings!$C$5:$C$1004-DATE($B$4,9,1)))/2)-((Bookings!$B$5:$B$1004+DATE($B$4,8,1)+ABS(Bookings!$B$5:$B$1004-DATE($B$4,8,1)))/2))+ABS(((Bookings!$C$5:$C$1004+DATE($B$4,9,1)-ABS(Bookings!$C$5:$C$1004-DATE($B$4,9,1)))/2)-((Bookings!$B$5:$B$1004+DATE($B$4,8,1)+ABS(Bookings!$B$5:$B$1004-DATE($B$4,8,1)))/2)))/2)*Bookings!$AC$5:$AC$1004) -> 0 | G17: =SUMPRODUCT(Bookings!$AA$5:$AA$1004*(($D$4="All properties")+(Bookings!$D$5:$D$1004=$D$4)>0)*(((((Bookings!$C$5:$C$1004+DATE($B$4,9,1)-ABS(Bookings!$C$5:$C$1004-DATE($B$4,9,1)))/2)-((Bookings!$B$5:$B$1004+DATE($B$4,8,1)+ABS(Bookings!$B$5:$B$1004-DATE($B$4,8,1)))/2))+ABS(((Bookings!$C$5:$C$1004+DATE($B$4,9,1)-ABS(Bookings!$C$5:$C$1004-DATE($B$4,9,1)))/2)-((Bookings!$B$5:$B$1004+DATE($B$4,8,1)+ABS(Bookings!$B$5:$B$1004-DATE($B$4,8,1)))/2)))/2)*Bookings!$AD$5:$AD$1004) -> 0 | H17: =IF($D$4="All properties",SUMIFS(Expenses!$F$5:$F$1004,Expenses!$A$5:$A$1004,">="&DATE($B$4,8,1),Expenses!$A$5:$A$1004,"<"&DATE($B$4,9,1)),SUMIFS(Expenses!$F$5:$F$1004,Expenses!$A$5:$A$1004,">="&DATE($B$4,8,1),Expenses!$A$5:$A$1004,"<"&DATE($B$4,9,1),Expenses!$B$5:$B$1004,$D$4)) -> 0 | I17: =F17-G17-H17 -> 0 | K17: =SUMPRODUCT((Properties!$A$5:$A$24<>"")*(($D$4="All properties")+(Properties!$A$5:$A$24=$D$4)>0)*(((DATE($B$4,9,1)-((Properties!$K$5:$K$24+DATE($B$4,8,1)+ABS(Properties!$K$5:$K$24-DATE($B$4,8,1)))/2))+ABS(DATE($B$4,9,1)-((Properties!$K$5:$K$24+DATE($B$4,8,1)+ABS(Properties!$K$5:$K$24-DATE($B$4,8,1)))/2)))/2)) -> 31 | L17: =SUMPRODUCT(Bookings!$AA$5:$AA$1004*(($D$4="All properties")+(Bookings!$D$5:$D$1004=$D$4)>0)*(((((Bookings!$C$5:$C$1004+DATE($B$4,9,1)-ABS(Bookings!$C$5:$C$1004-DATE($B$4,9,1)))/2)-((Bookings!$B$5:$B$1004+DATE($B$4,8,1)+ABS(Bookings!$B$5:$B$1004-DATE($B$4,8,1)))/2))+ABS(((Bookings!$C$5:$C$1004+DATE($B$4,9,1)-ABS(Bookings!$C$5:$C$1004-DATE($B$4,9,1)))/2)-((Bookings!$B$5:$B$1004+DATE($B$4,8,1)+ABS(Bookings!$B$5:$B$1004-DATE($B$4,8,1)))/2)))/2)*Bookings!$AB$5:$AB$1004) -> 0
A18: =TEXT(DATE($B$4,9,1),"mmm yyyy") -> Sep 2026 | B18: =SUMPRODUCT(Bookings!$AA$5:$AA$1004*(($D$4="All properties")+(Bookings!$D$5:$D$1004=$D$4)>0)*(((((Bookings!$C$5:$C$1004+DATE($B$4,10,1)-ABS(Bookings!$C$5:$C$1004-DATE($B$4,10,1)))/2)-((Bookings!$B$5:$B$1004+DATE($B$4,9,1)+ABS(Bookings!$B$5:$B$1004-DATE($B$4,9,1)))/2))+ABS(((Bookings!$C$5:$C$1004+DATE($B$4,10,1)-ABS(Bookings!$C$5:$C$1004-DATE($B$4,10,1)))/2)-((Bookings!$B$5:$B$1004+DATE($B$4,9,1)+ABS(Bookings!$B$5:$B$1004-DATE($B$4,9,1)))/2)))/2)) -> 0 | C18: =IF(K18=0,0,B18/K18) -> 0 | D18: =IF(B18=0,0,L18/B18) -> 0 | E18: =IF(K18=0,0,L18/K18) -> 0 | F18: =SUMPRODUCT(Bookings!$AA$5:$AA$1004*(($D$4="All properties")+(Bookings!$D$5:$D$1004=$D$4)>0)*(((((Bookings!$C$5:$C$1004+DATE($B$4,10,1)-ABS(Bookings!$C$5:$C$1004-DATE($B$4,10,1)))/2)-((Bookings!$B$5:$B$1004+DATE($B$4,9,1)+ABS(Bookings!$B$5:$B$1004-DATE($B$4,9,1)))/2))+ABS(((Bookings!$C$5:$C$1004+DATE($B$4,10,1)-ABS(Bookings!$C$5:$C$1004-DATE($B$4,10,1)))/2)-((Bookings!$B$5:$B$1004+DATE($B$4,9,1)+ABS(Bookings!$B$5:$B$1004-DATE($B$4,9,1)))/2)))/2)*Bookings!$AC$5:$AC$1004) -> 0 | G18: =SUMPRODUCT(Bookings!$AA$5:$AA$1004*(($D$4="All properties")+(Bookings!$D$5:$D$1004=$D$4)>0)*(((((Bookings!$C$5:$C$1004+DATE($B$4,10,1)-ABS(Bookings!$C$5:$C$1004-DATE($B$4,10,1)))/2)-((Bookings!$B$5:$B$1004+DATE($B$4,9,1)+ABS(Bookings!$B$5:$B$1004-DATE($B$4,9,1)))/2))+ABS(((Bookings!$C$5:$C$1004+DATE($B$4,10,1)-ABS(Bookings!$C$5:$C$1004-DATE($B$4,10,1)))/2)-((Bookings!$B$5:$B$1004+DATE($B$4,9,1)+ABS(Bookings!$B$5:$B$1004-DATE($B$4,9,1)))/2)))/2)*Bookings!$AD$5:$AD$1004) -> 0 | H18: =IF($D$4="All properties",SUMIFS(Expenses!$F$5:$F$1004,Expenses!$A$5:$A$1004,">="&DATE($B$4,9,1),Expenses!$A$5:$A$1004,"<"&DATE($B$4,10,1)),SUMIFS(Expenses!$F$5:$F$1004,Expenses!$A$5:$A$1004,">="&DATE($B$4,9,1),Expenses!$A$5:$A$1004,"<"&DATE($B$4,10,1),Expenses!$B$5:$B$1004,$D$4)) -> 0 | I18: =F18-G18-H18 -> 0 | K18: =SUMPRODUCT((Properties!$A$5:$A$24<>"")*(($D$4="All properties")+(Properties!$A$5:$A$24=$D$4)>0)*(((DATE($B$4,10,1)-((Properties!$K$5:$K$24+DATE($B$4,9,1)+ABS(Properties!$K$5:$K$24-DATE($B$4,9,1)))/2))+ABS(DATE($B$4,10,1)-((Properties!$K$5:$K$24+DATE($B$4,9,1)+ABS(Properties!$K$5:$K$24-DATE($B$4,9,1)))/2)))/2)) -> 30 | L18: =SUMPRODUCT(Bookings!$AA$5:$AA$1004*(($D$4="All properties")+(Bookings!$D$5:$D$1004=$D$4)>0)*(((((Bookings!$C$5:$C$1004+DATE($B$4,10,1)-ABS(Bookings!$C$5:$C$1004-DATE($B$4,10,1)))/2)-((Bookings!$B$5:$B$1004+DATE($B$4,9,1)+ABS(Bookings!$B$5:$B$1004-DATE($B$4,9,1)))/2))+ABS(((Bookings!$C$5:$C$1004+DATE($B$4,10,1)-ABS(Bookings!$C$5:$C$1004-DATE($B$4,10,1)))/2)-((Bookings!$B$5:$B$1004+DATE($B$4,9,1)+ABS(Bookings!$B$5:$B$1004-DATE($B$4,9,1)))/2)))/2)*Bookings!$AB$5:$AB$1004) -> 0
A19: =TEXT(DATE($B$4,10,1),"mmm yyyy") -> Oct 2026 | B19: =SUMPRODUCT(Bookings!$AA$5:$AA$1004*(($D$4="All properties")+(Bookings!$D$5:$D$1004=$D$4)>0)*(((((Bookings!$C$5:$C$1004+DATE($B$4,11,1)-ABS(Bookings!$C$5:$C$1004-DATE($B$4,11,1)))/2)-((Bookings!$B$5:$B$1004+DATE($B$4,10,1)+ABS(Bookings!$B$5:$B$1004-DATE($B$4,10,1)))/2))+ABS(((Bookings!$C$5:$C$1004+DATE($B$4,11,1)-ABS(Bookings!$C$5:$C$1004-DATE($B$4,11,1)))/2)-((Bookings!$B$5:$B$1004+DATE($B$4,10,1)+ABS(Bookings!$B$5:$B$1004-DATE($B$4,10,1)))/2)))/2)) -> 5 | C19: =IF(K19=0,0,B19/K19) -> 0.16129032 | D19: =IF(B19=0,0,L19/B19) -> 201 | E19: =IF(K19=0,0,L19/K19) -> 32.419355 | F19: =SUMPRODUCT(Bookings!$AA$5:$AA$1004*(($D$4="All properties")+(Bookings!$D$5:$D$1004=$D$4)>0)*(((((Bookings!$C$5:$C$1004+DATE($B$4,11,1)-ABS(Bookings!$C$5:$C$1004-DATE($B$4,11,1)))/2)-((Bookings!$B$5:$B$1004+DATE($B$4,10,1)+ABS(Bookings!$B$5:$B$1004-DATE($B$4,10,1)))/2))+ABS(((Bookings!$C$5:$C$1004+DATE($B$4,11,1)-ABS(Bookings!$C$5:$C$1004-DATE($B$4,11,1)))/2)-((Bookings!$B$5:$B$1004+DATE($B$4,10,1)+ABS(Bookings!$B$5:$B$1004-DATE($B$4,10,1)))/2)))/2)*Bookings!$AC$5:$AC$1004) -> 1241.6 | G19: =SUMPRODUCT(Bookings!$AA$5:$AA$1004*(($D$4="All properties")+(Bookings!$D$5:$D$1004=$D$4)>0)*(((((Bookings!$C$5:$C$1004+DATE($B$4,11,1)-ABS(Bookings!$C$5:$C$1004-DATE($B$4,11,1)))/2)-((Bookings!$B$5:$B$1004+DATE($B$4,10,1)+ABS(Bookings!$B$5:$B$1004-DATE($B$4,10,1)))/2))+ABS(((Bookings!$C$5:$C$1004+DATE($B$4,11,1)-ABS(Bookings!$C$5:$C$1004-DATE($B$4,11,1)))/2)-((Bookings!$B$5:$B$1004+DATE($B$4,10,1)+ABS(Bookings!$B$5:$B$1004-DATE($B$4,10,1)))/2)))/2)*Bookings!$AD$5:$AD$1004) -> 130 | H19: =IF($D$4="All properties",SUMIFS(Expenses!$F$5:$F$1004,Expenses!$A$5:$A$1004,">="&DATE($B$4,10,1),Expenses!$A$5:$A$1004,"<"&DATE($B$4,11,1)),SUMIFS(Expenses!$F$5:$F$1004,Expenses!$A$5:$A$1004,">="&DATE($B$4,10,1),Expenses!$A$5:$A$1004,"<"&DATE($B$4,11,1),Expenses!$B$5:$B$1004,$D$4)) -> 162.17 | I19: =F19-G19-H19 -> 949.43 | K19: =SUMPRODUCT((Properties!$A$5:$A$24<>"")*(($D$4="All properties")+(Properties!$A$5:$A$24=$D$4)>0)*(((DATE($B$4,11,1)-((Properties!$K$5:$K$24+DATE($B$4,10,1)+ABS(Properties!$K$5:$K$24-DATE($B$4,10,1)))/2))+ABS(DATE($B$4,11,1)-((Properties!$K$5:$K$24+DATE($B$4,10,1)+ABS(Properties!$K$5:$K$24-DATE($B$4,10,1)))/2)))/2)) -> 31 | L19: =SUMPRODUCT(Bookings!$AA$5:$AA$1004*(($D$4="All properties")+(Bookings!$D$5:$D$1004=$D$4)>0)*(((((Bookings!$C$5:$C$1004+DATE($B$4,11,1)-ABS(Bookings!$C$5:$C$1004-DATE($B$4,11,1)))/2)-((Bookings!$B$5:$B$1004+DATE($B$4,10,1)+ABS(Bookings!$B$5:$B$1004-DATE($B$4,10,1)))/2))+ABS(((Bookings!$C$5:$C$1004+DATE($B$4,11,1)-ABS(Bookings!$C$5:$C$1004-DATE($B$4,11,1)))/2)-((Bookings!$B$5:$B$1004+DATE($B$4,10,1)+ABS(Bookings!$B$5:$B$1004-DATE($B$4,10,1)))/2)))/2)*Bookings!$AB$5:$AB$1004) -> 1005
A20: =TEXT(DATE($B$4,11,1),"mmm yyyy") -> Nov 2026 | B20: =SUMPRODUCT(Bookings!$AA$5:$AA$1004*(($D$4="All properties")+(Bookings!$D$5:$D$1004=$D$4)>0)*(((((Bookings!$C$5:$C$1004+DATE($B$4,12,1)-ABS(Bookings!$C$5:$C$1004-DATE($B$4,12,1)))/2)-((Bookings!$B$5:$B$1004+DATE($B$4,11,1)+ABS(Bookings!$B$5:$B$1004-DATE($B$4,11,1)))/2))+ABS(((Bookings!$C$5:$C$1004+DATE($B$4,12,1)-ABS(Bookings!$C$5:$C$1004-DATE($B$4,12,1)))/2)-((Bookings!$B$5:$B$1004+DATE($B$4,11,1)+ABS(Bookings!$B$5:$B$1004-DATE($B$4,11,1)))/2)))/2)) -> 0 | C20: =IF(K20=0,0,B20/K20) -> 0 | D20: =IF(B20=0,0,L20/B20) -> 0 | E20: =IF(K20=0,0,L20/K20) -> 0 | F20: =SUMPRODUCT(Bookings!$AA$5:$AA$1004*(($D$4="All properties")+(Bookings!$D$5:$D$1004=$D$4)>0)*(((((Bookings!$C$5:$C$1004+DATE($B$4,12,1)-ABS(Bookings!$C$5:$C$1004-DATE($B$4,12,1)))/2)-((Bookings!$B$5:$B$1004+DATE($B$4,11,1)+ABS(Bookings!$B$5:$B$1004-DATE($B$4,11,1)))/2))+ABS(((Bookings!$C$5:$C$1004+DATE($B$4,12,1)-ABS(Bookings!$C$5:$C$1004-DATE($B$4,12,1)))/2)-((Bookings!$B$5:$B$1004+DATE($B$4,11,1)+ABS(Bookings!$B$5:$B$1004-DATE($B$4,11,1)))/2)))/2)*Bookings!$AC$5:$AC$1004) -> 0 | G20: =SUMPRODUCT(Bookings!$AA$5:$AA$1004*(($D$4="All properties")+(Bookings!$D$5:$D$1004=$D$4)>0)*(((((Bookings!$C$5:$C$1004+DATE($B$4,12,1)-ABS(Bookings!$C$5:$C$1004-DATE($B$4,12,1)))/2)-((Bookings!$B$5:$B$1004+DATE($B$4,11,1)+ABS(Bookings!$B$5:$B$1004-DATE($B$4,11,1)))/2))+ABS(((Bookings!$C$5:$C$1004+DATE($B$4,12,1)-ABS(Bookings!$C$5:$C$1004-DATE($B$4,12,1)))/2)-((Bookings!$B$5:$B$1004+DATE($B$4,11,1)+ABS(Bookings!$B$5:$B$1004-DATE($B$4,11,1)))/2)))/2)*Bookings!$AD$5:$AD$1004) -> 0 | H20: =IF($D$4="All properties",SUMIFS(Expenses!$F$5:$F$1004,Expenses!$A$5:$A$1004,">="&DATE($B$4,11,1),Expenses!$A$5:$A$1004,"<"&DATE($B$4,12,1)),SUMIFS(Expenses!$F$5:$F$1004,Expenses!$A$5:$A$1004,">="&DATE($B$4,11,1),Expenses!$A$5:$A$1004,"<"&DATE($B$4,12,1),Expenses!$B$5:$B$1004,$D$4)) -> 0 | I20: =F20-G20-H20 -> 0 | K20: =SUMPRODUCT((Properties!$A$5:$A$24<>"")*(($D$4="All properties")+(Properties!$A$5:$A$24=$D$4)>0)*(((DATE($B$4,12,1)-((Properties!$K$5:$K$24+DATE($B$4,11,1)+ABS(Properties!$K$5:$K$24-DATE($B$4,11,1)))/2))+ABS(DATE($B$4,12,1)-((Properties!$K$5:$K$24+DATE($B$4,11,1)+ABS(Properties!$K$5:$K$24-DATE($B$4,11,1)))/2)))/2)) -> 30 | L20: =SUMPRODUCT(Bookings!$AA$5:$AA$1004*(($D$4="All properties")+(Bookings!$D$5:$D$1004=$D$4)>0)*(((((Bookings!$C$5:$C$1004+DATE($B$4,12,1)-ABS(Bookings!$C$5:$C$1004-DATE($B$4,12,1)))/2)-((Bookings!$B$5:$B$1004+DATE($B$4,11,1)+ABS(Bookings!$B$5:$B$1004-DATE($B$4,11,1)))/2))+ABS(((Bookings!$C$5:$C$1004+DATE($B$4,12,1)-ABS(Bookings!$C$5:$C$1004-DATE($B$4,12,1)))/2)-((Bookings!$B$5:$B$1004+DATE($B$4,11,1)+ABS(Bookings!$B$5:$B$1004-DATE($B$4,11,1)))/2)))/2)*Bookings!$AB$5:$AB$1004) -> 0
A21: =TEXT(DATE($B$4,12,1),"mmm yyyy") -> Dec 2026 | B21: =SUMPRODUCT(Bookings!$AA$5:$AA$1004*(($D$4="All properties")+(Bookings!$D$5:$D$1004=$D$4)>0)*(((((Bookings!$C$5:$C$1004+DATE($B$4,13,1)-ABS(Bookings!$C$5:$C$1004-DATE($B$4,13,1)))/2)-((Bookings!$B$5:$B$1004+DATE($B$4,12,1)+ABS(Bookings!$B$5:$B$1004-DATE($B$4,12,1)))/2))+ABS(((Bookings!$C$5:$C$1004+DATE($B$4,13,1)-ABS(Bookings!$C$5:$C$1004-DATE($B$4,13,1)))/2)-((Bookings!$B$5:$B$1004+DATE($B$4,12,1)+ABS(Bookings!$B$5:$B$1004-DATE($B$4,12,1)))/2)))/2)) -> 0 | C21: =IF(K21=0,0,B21/K21) -> 0 | D21: =IF(B21=0,0,L21/B21) -> 0 | E21: =IF(K21=0,0,L21/K21) -> 0 | F21: =SUMPRODUCT(Bookings!$AA$5:$AA$1004*(($D$4="All properties")+(Bookings!$D$5:$D$1004=$D$4)>0)*(((((Bookings!$C$5:$C$1004+DATE($B$4,13,1)-ABS(Bookings!$C$5:$C$1004-DATE($B$4,13,1)))/2)-((Bookings!$B$5:$B$1004+DATE($B$4,12,1)+ABS(Bookings!$B$5:$B$1004-DATE($B$4,12,1)))/2))+ABS(((Bookings!$C$5:$C$1004+DATE($B$4,13,1)-ABS(Bookings!$C$5:$C$1004-DATE($B$4,13,1)))/2)-((Bookings!$B$5:$B$1004+DATE($B$4,12,1)+ABS(Bookings!$B$5:$B$1004-DATE($B$4,12,1)))/2)))/2)*Bookings!$AC$5:$AC$1004) -> 0 | G21: =SUMPRODUCT(Bookings!$AA$5:$AA$1004*(($D$4="All properties")+(Bookings!$D$5:$D$1004=$D$4)>0)*(((((Bookings!$C$5:$C$1004+DATE($B$4,13,1)-ABS(Bookings!$C$5:$C$1004-DATE($B$4,13,1)))/2)-((Bookings!$B$5:$B$1004+DATE($B$4,12,1)+ABS(Bookings!$B$5:$B$1004-DATE($B$4,12,1)))/2))+ABS(((Bookings!$C$5:$C$1004+DATE($B$4,13,1)-ABS(Bookings!$C$5:$C$1004-DATE($B$4,13,1)))/2)-((Bookings!$B$5:$B$1004+DATE($B$4,12,1)+ABS(Bookings!$B$5:$B$1004-DATE($B$4,12,1)))/2)))/2)*Bookings!$AD$5:$AD$1004) -> 0 | H21: =IF($D$4="All properties",SUMIFS(Expenses!$F$5:$F$1004,Expenses!$A$5:$A$1004,">="&DATE($B$4,12,1),Expenses!$A$5:$A$1004,"<"&DATE($B$4,13,1)),SUMIFS(Expenses!$F$5:$F$1004,Expenses!$A$5:$A$1004,">="&DATE($B$4,12,1),Expenses!$A$5:$A$1004,"<"&DATE($B$4,13,1),Expenses!$B$5:$B$1004,$D$4)) -> 0 | I21: =F21-G21-H21 -> 0 | K21: =SUMPRODUCT((Properties!$A$5:$A$24<>"")*(($D$4="All properties")+(Properties!$A$5:$A$24=$D$4)>0)*(((DATE($B$4,13,1)-((Properties!$K$5:$K$24+DATE($B$4,12,1)+ABS(Properties!$K$5:$K$24-DATE($B$4,12,1)))/2))+ABS(DATE($B$4,13,1)-((Properties!$K$5:$K$24+DATE($B$4,12,1)+ABS(Properties!$K$5:$K$24-DATE($B$4,12,1)))/2)))/2)) -> 31 | L21: =SUMPRODUCT(Bookings!$AA$5:$AA$1004*(($D$4="All properties")+(Bookings!$D$5:$D$1004=$D$4)>0)*(((((Bookings!$C$5:$C$1004+DATE($B$4,13,1)-ABS(Bookings!$C$5:$C$1004-DATE($B$4,13,1)))/2)-((Bookings!$B$5:$B$1004+DATE($B$4,12,1)+ABS(Bookings!$B$5:$B$1004-DATE($B$4,12,1)))/2))+ABS(((Bookings!$C$5:$C$1004+DATE($B$4,13,1)-ABS(Bookings!$C$5:$C$1004-DATE($B$4,13,1)))/2)-((Bookings!$B$5:$B$1004+DATE($B$4,12,1)+ABS(Bookings!$B$5:$B$1004-DATE($B$4,12,1)))/2)))/2)*Bookings!$AB$5:$AB$1004) -> 0
A22: Year total | B22: =SUM(B10:B21) -> 5 | C22: =IF(K22=0,0,B22/K22) -> 0.01369863 | D22: =IF(B22=0,0,L22/B22) -> 201 | E22: =IF(K22=0,0,L22/K22) -> 2.7534247 | F22: =SUM(F10:F21) -> 1241.6 | G22: =SUM(G10:G21) -> 130 | H22: =SUM(H10:H21) -> 162.17 | I22: =SUM(I10:I21) -> 949.43 | K22: =SUM(K10:K21) -> 365 | L22: =SUM(L10:L21) -> 1005
A25: BY PROPERTY
A26: Property | B26: Nights booked | C26: Occupancy | D26: ADR | E26: RevPAR | F26: Payout | G26: Cleaning costs | H26: Expenses | I26: Profit
A27: =IF(Properties!A5="","",Properties!A5) -> EXAMPLE – Lakeview Cabin | B27: =IF($A27="","",SUMPRODUCT(Bookings!$AA$5:$AA$1004*(($A27="All properties")+(Bookings!$D$5:$D$1004=$A27)>0)*(((((Bookings!$C$5:$C$1004+DATE($B$4+1,1,1)-ABS(Bookings!$C$5:$C$1004-DATE($B$4+1,1,1)))/2)-((Bookings!$B$5:$B$1004+DATE($B$4,1,1)+ABS(Bookings!$B$5:$B$1004-DATE($B$4,1,1)))/2))+ABS(((Bookings!$C$5:$C$1004+DATE($B$4+1,1,1)-ABS(Bookings!$C$5:$C$1004-DATE($B$4+1,1,1)))/2)-((Bookings!$B$5:$B$1004+DATE($B$4,1,1)+ABS(Bookings!$B$5:$B$1004-DATE($B$4,1,1)))/2)))/2))) -> 5 | C27: =IF($A27="","",IF(K27=0,0,B27/K27)) -> 0.01369863 | D27: =IF($A27="","",IF(B27=0,0,L27/B27)) -> 201 | E27: =IF($A27="","",IF(K27=0,0,L27/K27)) -> 2.7534247 | F27: =IF($A27="","",SUMPRODUCT(Bookings!$AA$5:$AA$1004*(($A27="All properties")+(Bookings!$D$5:$D$1004=$A27)>0)*(((((Bookings!$C$5:$C$1004+DATE($B$4+1,1,1)-ABS(Bookings!$C$5:$C$1004-DATE($B$4+1,1,1)))/2)-((Bookings!$B$5:$B$1004+DATE($B$4,1,1)+ABS(Bookings!$B$5:$B$1004-DATE($B$4,1,1)))/2))+ABS(((Bookings!$C$5:$C$1004+DATE($B$4+1,1,1)-ABS(Bookings!$C$5:$C$1004-DATE($B$4+1,1,1)))/2)-((Bookings!$B$5:$B$1004+DATE($B$4,1,1)+ABS(Bookings!$B$5:$B$1004-DATE($B$4,1,1)))/2)))/2)*Bookings!$AC$5:$AC$1004)) -> 1241.6 | G27: =IF($A27="","",SUMPRODUCT(Bookings!$AA$5:$AA$1004*(($A27="All properties")+(Bookings!$D$5:$D$1004=$A27)>0)*(((((Bookings!$C$5:$C$1004+DATE($B$4+1,1,1)-ABS(Bookings!$C$5:$C$1004-DATE($B$4+1,1,1)))/2)-((Bookings!$B$5:$B$1004+DATE($B$4,1,1)+ABS(Bookings!$B$5:$B$1004-DATE($B$4,1,1)))/2))+ABS(((Bookings!$C$5:$C$1004+DATE($B$4+1,1,1)-ABS(Bookings!$C$5:$C$1004-DATE($B$4+1,1,1)))/2)-((Bookings!$B$5:$B$1004+DATE($B$4,1,1)+ABS(Bookings!$B$5:$B$1004-DATE($B$4,1,1)))/2)))/2)*Bookings!$AD$5:$AD$1004)) -> 130 | H27: =IF($A27="","",SUMIFS(Expenses!$F$5:$F$1004,Expenses!$A$5:$A$1004,">="&DATE($B$4,1,1),Expenses!$A$5:$A$1004,"<"&DATE($B$4+1,1,1),Expenses!$B$5:$B$1004,$A27)) -> 142.18 | I27: =IF($A27="","",F27-G27-H27) -> 969.42 | K27: =IF($A27="","",SUMPRODUCT((Properties!$A$5:$A$24<>"")*(($A27="All properties")+(Properties!$A$5:$A$24=$A27)>0)*(((DATE($B$4+1,1,1)-((Properties!$K$5:$K$24+DATE($B$4,1,1)+ABS(Properties!$K$5:$K$24-DATE($B$4,1,1)))/2))+ABS(DATE($B$4+1,1,1)-((Properties!$K$5:$K$24+DATE($B$4,1,1)+ABS(Properties!$K$5:$K$24-DATE($B$4,1,1)))/2)))/2))) -> 365 | L27: =IF($A27="","",SUMPRODUCT(Bookings!$AA$5:$AA$1004*(($A27="All properties")+(Bookings!$D$5:$D$1004=$A27)>0)*(((((Bookings!$C$5:$C$1004+DATE($B$4+1,1,1)-ABS(Bookings!$C$5:$C$1004-DATE($B$4+1,1,1)))/2)-((Bookings!$B$5:$B$1004+DATE($B$4,1,1)+ABS(Bookings!$B$5:$B$1004-DATE($B$4,1,1)))/2))+ABS(((Bookings!$C$5:$C$1004+DATE($B$4+1,1,1)-ABS(Bookings!$C$5:$C$1004-DATE($B$4+1,1,1)))/2)-((Bookings!$B$5:$B$1004+DATE($B$4,1,1)+ABS(Bookings!$B$5:$B$1004-DATE($B$4,1,1)))/2)))/2)*Bookings!$AB$5:$AB$1004)) -> 1005
A28: =IF(Properties!A6="","",Properties!A6) | B28: =IF($A28="","",SUMPRODUCT(Bookings!$AA$5:$AA$1004*(($A28="All properties")+(Bookings!$D$5:$D$1004=$A28)>0)*(((((Bookings!$C$5:$C$1004+DATE($B$4+1,1,1)-ABS(Bookings!$C$5:$C$1004-DATE($B$4+1,1,1)))/2)-((Bookings!$B$5:$B$1004+DATE($B$4,1,1)+ABS(Bookings!$B$5:$B$1004-DATE($B$4,1,1)))/2))+ABS(((Bookings!$C$5:$C$1004+DATE($B$4+1,1,1)-ABS(Bookings!$C$5:$C$1004-DATE($B$4+1,1,1)))/2)-((Bookings!$B$5:$B$1004+DATE($B$4,1,1)+ABS(Bookings!$B$5:$B$1004-DATE($B$4,1,1)))/2)))/2))) | C28: =IF($A28="","",IF(K28=0,0,B28/K28)) | D28: =IF($A28="","",IF(B28=0,0,L28/B28)) | E28: =IF($A28="","",IF(K28=0,0,L28/K28)) | F28: =IF($A28="","",SUMPRODUCT(Bookings!$AA$5:$AA$1004*(($A28="All properties")+(Bookings!$D$5:$D$1004=$A28)>0)*(((((Bookings!$C$5:$C$1004+DATE($B$4+1,1,1)-ABS(Bookings!$C$5:$C$1004-DATE($B$4+1,1,1)))/2)-((Bookings!$B$5:$B$1004+DATE($B$4,1,1)+ABS(Bookings!$B$5:$B$1004-DATE($B$4,1,1)))/2))+ABS(((Bookings!$C$5:$C$1004+DATE($B$4+1,1,1)-ABS(Bookings!$C$5:$C$1004-DATE($B$4+1,1,1)))/2)-((Bookings!$B$5:$B$1004+DATE($B$4,1,1)+ABS(Bookings!$B$5:$B$1004-DATE($B$4,1,1)))/2)))/2)*Bookings!$AC$5:$AC$1004)) | G28: =IF($A28="","",SUMPRODUCT(Bookings!$AA$5:$AA$1004*(($A28="All properties")+(Bookings!$D$5:$D$1004=$A28)>0)*(((((Bookings!$C$5:$C$1004+DATE($B$4+1,1,1)-ABS(Bookings!$C$5:$C$1004-DATE($B$4+1,1,1)))/2)-((Bookings!$B$5:$B$1004+DATE($B$4,1,1)+ABS(Bookings!$B$5:$B$1004-DATE($B$4,1,1)))/2))+ABS(((Bookings!$C$5:$C$1004+DATE($B$4+1,1,1)-ABS(Bookings!$C$5:$C$1004-DATE($B$4+1,1,1)))/2)-((Bookings!$B$5:$B$1004+DATE($B$4,1,1)+ABS(Bookings!$B$5:$B$1004-DATE($B$4,1,1)))/2)))/2)*Bookings!$AD$5:$AD$1004)) | H28: =IF($A28="","",SUMIFS(Expenses!$F$5:$F$1004,Expenses!$A$5:$A$1004,">="&DATE($B$4,1,1),Expenses!$A$5:$A$1004,"<"&DATE($B$4+1,1,1),Expenses!$B$5:$B$1004,$A28)) | I28: =IF($A28="","",F28-G28-H28) | K28: =IF($A28="","",SUMPRODUCT((Properties!$A$5:$A$24<>"")*(($A28="All properties")+(Properties!$A$5:$A$24=$A28)>0)*(((DATE($B$4+1,1,1)-((Properties!$K$5:$K$24+DATE($B$4,1,1)+ABS(Properties!$K$5:$K$24-DATE($B$4,1,1)))/2))+ABS(DATE($B$4+1,1,1)-((Properties!$K$5:$K$24+DATE($B$4,1,1)+ABS(Properties!$K$5:$K$24-DATE($B$4,1,1)))/2)))/2))) | L28: =IF($A28="","",SUMPRODUCT(Bookings!$AA$5:$AA$1004*(($A28="All properties")+(Bookings!$D$5:$D$1004=$A28)>0)*(((((Bookings!$C$5:$C$1004+DATE($B$4+1,1,1)-ABS(Bookings!$C$5:$C$1004-DATE($B$4+1,1,1)))/2)-((Bookings!$B$5:$B$1004+DATE($B$4,1,1)+ABS(Bookings!$B$5:$B$1004-DATE($B$4,1,1)))/2))+ABS(((Bookings!$C$5:$C$1004+DATE($B$4+1,1,1)-ABS(Bookings!$C$5:$C$1004-DATE($B$4+1,1,1)))/2)-((Bookings!$B$5:$B$1004+DATE($B$4,1,1)+ABS(Bookings!$B$5:$B$1004-DATE($B$4,1,1)))/2)))/2)*Bookings!$AB$5:$AB$1004))
A29: =IF(Properties!A7="","",Properties!A7) | B29: =IF($A29="","",SUMPRODUCT(Bookings!$AA$5:$AA$1004*(($A29="All properties")+(Bookings!$D$5:$D$1004=$A29)>0)*(((((Bookings!$C$5:$C$1004+DATE($B$4+1,1,1)-ABS(Bookings!$C$5:$C$1004-DATE($B$4+1,1,1)))/2)-((Bookings!$B$5:$B$1004+DATE($B$4,1,1)+ABS(Bookings!$B$5:$B$1004-DATE($B$4,1,1)))/2))+ABS(((Bookings!$C$5:$C$1004+DATE($B$4+1,1,1)-ABS(Bookings!$C$5:$C$1004-DATE($B$4+1,1,1)))/2)-((Bookings!$B$5:$B$1004+DATE($B$4,1,1)+ABS(Bookings!$B$5:$B$1004-DATE($B$4,1,1)))/2)))/2))) | C29: =IF($A29="","",IF(K29=0,0,B29/K29)) | D29: =IF($A29="","",IF(B29=0,0,L29/B29)) | E29: =IF($A29="","",IF(K29=0,0,L29/K29)) | F29: =IF($A29="","",SUMPRODUCT(Bookings!$AA$5:$AA$1004*(($A29="All properties")+(Bookings!$D$5:$D$1004=$A29)>0)*(((((Bookings!$C$5:$C$1004+DATE($B$4+1,1,1)-ABS(Bookings!$C$5:$C$1004-DATE($B$4+1,1,1)))/2)-((Bookings!$B$5:$B$1004+DATE($B$4,1,1)+ABS(Bookings!$B$5:$B$1004-DATE($B$4,1,1)))/2))+ABS(((Bookings!$C$5:$C$1004+DATE($B$4+1,1,1)-ABS(Bookings!$C$5:$C$1004-DATE($B$4+1,1,1)))/2)-((Bookings!$B$5:$B$1004+DATE($B$4,1,1)+ABS(Bookings!$B$5:$B$1004-DATE($B$4,1,1)))/2)))/2)*Bookings!$AC$5:$AC$1004)) | G29: =IF($A29="","",SUMPRODUCT(Bookings!$AA$5:$AA$1004*(($A29="All properties")+(Bookings!$D$5:$D$1004=$A29)>0)*(((((Bookings!$C$5:$C$1004+DATE($B$4+1,1,1)-ABS(Bookings!$C$5:$C$1004-DATE($B$4+1,1,1)))/2)-((Bookings!$B$5:$B$1004+DATE($B$4,1,1)+ABS(Bookings!$B$5:$B$1004-DATE($B$4,1,1)))/2))+ABS(((Bookings!$C$5:$C$1004+DATE($B$4+1,1,1)-ABS(Bookings!$C$5:$C$1004-DATE($B$4+1,1,1)))/2)-((Bookings!$B$5:$B$1004+DATE($B$4,1,1)+ABS(Bookings!$B$5:$B$1004-DATE($B$4,1,1)))/2)))/2)*Bookings!$AD$5:$AD$1004)) | H29: =IF($A29="","",SUMIFS(Expenses!$F$5:$F$1004,Expenses!$A$5:$A$1004,">="&DATE($B$4,1,1),Expenses!$A$5:$A$1004,"<"&DATE($B$4+1,1,1),Expenses!$B$5:$B$1004,$A29)) | I29: =IF($A29="","",F29-G29-H29) | K29: =IF($A29="","",SUMPRODUCT((Properties!$A$5:$A$24<>"")*(($A29="All properties")+(Properties!$A$5:$A$24=$A29)>0)*(((DATE($B$4+1,1,1)-((Properties!$K$5:$K$24+DATE($B$4,1,1)+ABS(Properties!$K$5:$K$24-DATE($B$4,1,1)))/2))+ABS(DATE($B$4+1,1,1)-((Properties!$K$5:$K$24+DATE($B$4,1,1)+ABS(Properties!$K$5:$K$24-DATE($B$4,1,1)))/2)))/2))) | L29: =IF($A29="","",SUMPRODUCT(Bookings!$AA$5:$AA$1004*(($A29="All properties")+(Bookings!$D$5:$D$1004=$A29)>0)*(((((Bookings!$C$5:$C$1004+DATE($B$4+1,1,1)-ABS(Bookings!$C$5:$C$1004-DATE($B$4+1,1,1)))/2)-((Bookings!$B$5:$B$1004+DATE($B$4,1,1)+ABS(Bookings!$B$5:$B$1004-DATE($B$4,1,1)))/2))+ABS(((Bookings!$C$5:$C$1004+DATE($B$4+1,1,1)-ABS(Bookings!$C$5:$C$1004-DATE($B$4+1,1,1)))/2)-((Bookings!$B$5:$B$1004+DATE($B$4,1,1)+ABS(Bookings!$B$5:$B$1004-DATE($B$4,1,1)))/2)))/2)*Bookings!$AB$5:$AB$1004))
A30: =IF(Properties!A8="","",Properties!A8) | B30: =IF($A30="","",SUMPRODUCT(Bookings!$AA$5:$AA$1004*(($A30="All properties")+(Bookings!$D$5:$D$1004=$A30)>0)*(((((Bookings!$C$5:$C$1004+DATE($B$4+1,1,1)-ABS(Bookings!$C$5:$C$1004-DATE($B$4+1,1,1)))/2)-((Bookings!$B$5:$B$1004+DATE($B$4,1,1)+ABS(Bookings!$B$5:$B$1004-DATE($B$4,1,1)))/2))+ABS(((Bookings!$C$5:$C$1004+DATE($B$4+1,1,1)-ABS(Bookings!$C$5:$C$1004-DATE($B$4+1,1,1)))/2)-((Bookings!$B$5:$B$1004+DATE($B$4,1,1)+ABS(Bookings!$B$5:$B$1004-DATE($B$4,1,1)))/2)))/2))) | C30: =IF($A30="","",IF(K30=0,0,B30/K30)) | D30: =IF($A30="","",IF(B30=0,0,L30/B30)) | E30: =IF($A30="","",IF(K30=0,0,L30/K30)) | F30: =IF($A30="","",SUMPRODUCT(Bookings!$AA$5:$AA$1004*(($A30="All properties")+(Bookings!$D$5:$D$1004=$A30)>0)*(((((Bookings!$C$5:$C$1004+DATE($B$4+1,1,1)-ABS(Bookings!$C$5:$C$1004-DATE($B$4+1,1,1)))/2)-((Bookings!$B$5:$B$1004+DATE($B$4,1,1)+ABS(Bookings!$B$5:$B$1004-DATE($B$4,1,1)))/2))+ABS(((Bookings!$C$5:$C$1004+DATE($B$4+1,1,1)-ABS(Bookings!$C$5:$C$1004-DATE($B$4+1,1,1)))/2)-((Bookings!$B$5:$B$1004+DATE($B$4,1,1)+ABS(Bookings!$B$5:$B$1004-DATE($B$4,1,1)))/2)))/2)*Bookings!$AC$5:$AC$1004)) | G30: =IF($A30="","",SUMPRODUCT(Bookings!$AA$5:$AA$1004*(($A30="All properties")+(Bookings!$D$5:$D$1004=$A30)>0)*(((((Bookings!$C$5:$C$1004+DATE($B$4+1,1,1)-ABS(Bookings!$C$5:$C$1004-DATE($B$4+1,1,1)))/2)-((Bookings!$B$5:$B$1004+DATE($B$4,1,1)+ABS(Bookings!$B$5:$B$1004-DATE($B$4,1,1)))/2))+ABS(((Bookings!$C$5:$C$1004+DATE($B$4+1,1,1)-ABS(Bookings!$C$5:$C$1004-DATE($B$4+1,1,1)))/2)-((Bookings!$B$5:$B$1004+DATE($B$4,1,1)+ABS(Bookings!$B$5:$B$1004-DATE($B$4,1,1)))/2)))/2)*Bookings!$AD$5:$AD$1004)) | H30: =IF($A30="","",SUMIFS(Expenses!$F$5:$F$1004,Expenses!$A$5:$A$1004,">="&DATE($B$4,1,1),Expenses!$A$5:$A$1004,"<"&DATE($B$4+1,1,1),Expenses!$B$5:$B$1004,$A30)) | I30: =IF($A30="","",F30-G30-H30) | K30: =IF($A30="","",SUMPRODUCT((Properties!$A$5:$A$24<>"")*(($A30="All properties")+(Properties!$A$5:$A$24=$A30)>0)*(((DATE($B$4+1,1,1)-((Properties!$K$5:$K$24+DATE($B$4,1,1)+ABS(Properties!$K$5:$K$24-DATE($B$4,1,1)))/2))+ABS(DATE($B$4+1,1,1)-((Properties!$K$5:$K$24+DATE($B$4,1,1)+ABS(Properties!$K$5:$K$24-DATE($B$4,1,1)))/2)))/2))) | L30: =IF($A30="","",SUMPRODUCT(Bookings!$AA$5:$AA$1004*(($A30="All properties")+(Bookings!$D$5:$D$1004=$A30)>0)*(((((Bookings!$C$5:$C$1004+DATE($B$4+1,1,1)-ABS(Bookings!$C$5:$C$1004-DATE($B$4+1,1,1)))/2)-((Bookings!$B$5:$B$1004+DATE($B$4,1,1)+ABS(Bookings!$B$5:$B$1004-DATE($B$4,1,1)))/2))+ABS(((Bookings!$C$5:$C$1004+DATE($B$4+1,1,1)-ABS(Bookings!$C$5:$C$1004-DATE($B$4+1,1,1)))/2)-((Bookings!$B$5:$B$1004+DATE($B$4,1,1)+ABS(Bookings!$B$5:$B$1004-DATE($B$4,1,1)))/2)))/2)*Bookings!$AB$5:$AB$1004))
A31: =IF(Properties!A9="","",Properties!A9) | B31: =IF($A31="","",SUMPRODUCT(Bookings!$AA$5:$AA$1004*(($A31="All properties")+(Bookings!$D$5:$D$1004=$A31)>0)*(((((Bookings!$C$5:$C$1004+DATE($B$4+1,1,1)-ABS(Bookings!$C$5:$C$1004-DATE($B$4+1,1,1)))/2)-((Bookings!$B$5:$B$1004+DATE($B$4,1,1)+ABS(Bookings!$B$5:$B$1004-DATE($B$4,1,1)))/2))+ABS(((Bookings!$C$5:$C$1004+DATE($B$4+1,1,1)-ABS(Bookings!$C$5:$C$1004-DATE($B$4+1,1,1)))/2)-((Bookings!$B$5:$B$1004+DATE($B$4,1,1)+ABS(Bookings!$B$5:$B$1004-DATE($B$4,1,1)))/2)))/2))) | C31: =IF($A31="","",IF(K31=0,0,B31/K31)) | D31: =IF($A31="","",IF(B31=0,0,L31/B31)) | E31: =IF($A31="","",IF(K31=0,0,L31/K31)) | F31: =IF($A31="","",SUMPRODUCT(Bookings!$AA$5:$AA$1004*(($A31="All properties")+(Bookings!$D$5:$D$1004=$A31)>0)*(((((Bookings!$C$5:$C$1004+DATE($B$4+1,1,1)-ABS(Bookings!$C$5:$C$1004-DATE($B$4+1,1,1)))/2)-((Bookings!$B$5:$B$1004+DATE($B$4,1,1)+ABS(Bookings!$B$5:$B$1004-DATE($B$4,1,1)))/2))+ABS(((Bookings!$C$5:$C$1004+DATE($B$4+1,1,1)-ABS(Bookings!$C$5:$C$1004-DATE($B$4+1,1,1)))/2)-((Bookings!$B$5:$B$1004+DATE($B$4,1,1)+ABS(Bookings!$B$5:$B$1004-DATE($B$4,1,1)))/2)))/2)*Bookings!$AC$5:$AC$1004)) | G31: =IF($A31="","",SUMPRODUCT(Bookings!$AA$5:$AA$1004*(($A31="All properties")+(Bookings!$D$5:$D$1004=$A31)>0)*(((((Bookings!$C$5:$C$1004+DATE($B$4+1,1,1)-ABS(Bookings!$C$5:$C$1004-DATE($B$4+1,1,1)))/2)-((Bookings!$B$5:$B$1004+DATE($B$4,1,1)+ABS(Bookings!$B$5:$B$1004-DATE($B$4,1,1)))/2))+ABS(((Bookings!$C$5:$C$1004+DATE($B$4+1,1,1)-ABS(Bookings!$C$5:$C$1004-DATE($B$4+1,1,1)))/2)-((Bookings!$B$5:$B$1004+DATE($B$4,1,1)+ABS(Bookings!$B$5:$B$1004-DATE($B$4,1,1)))/2)))/2)*Bookings!$AD$5:$AD$1004)) | H31: =IF($A31="","",SUMIFS(Expenses!$F$5:$F$1004,Expenses!$A$5:$A$1004,">="&DATE($B$4,1,1),Expenses!$A$5:$A$1004,"<"&DATE($B$4+1,1,1),Expenses!$B$5:$B$1004,$A31)) | I31: =IF($A31="","",F31-G31-H31) | K31: =IF($A31="","",SUMPRODUCT((Properties!$A$5:$A$24<>"")*(($A31="All properties")+(Properties!$A$5:$A$24=$A31)>0)*(((DATE($B$4+1,1,1)-((Properties!$K$5:$K$24+DATE($B$4,1,1)+ABS(Properties!$K$5:$K$24-DATE($B$4,1,1)))/2))+ABS(DATE($B$4+1,1,1)-((Properties!$K$5:$K$24+DATE($B$4,1,1)+ABS(Properties!$K$5:$K$24-DATE($B$4,1,1)))/2)))/2))) | L31: =IF($A31="","",SUMPRODUCT(Bookings!$AA$5:$AA$1004*(($A31="All properties")+(Bookings!$D$5:$D$1004=$A31)>0)*(((((Bookings!$C$5:$C$1004+DATE($B$4+1,1,1)-ABS(Bookings!$C$5:$C$1004-DATE($B$4+1,1,1)))/2)-((Bookings!$B$5:$B$1004+DATE($B$4,1,1)+ABS(Bookings!$B$5:$B$1004-DATE($B$4,1,1)))/2))+ABS(((Bookings!$C$5:$C$1004+DATE($B$4+1,1,1)-ABS(Bookings!$C$5:$C$1004-DATE($B$4+1,1,1)))/2)-((Bookings!$B$5:$B$1004+DATE($B$4,1,1)+ABS(Bookings!$B$5:$B$1004-DATE($B$4,1,1)))/2)))/2)*Bookings!$AB$5:$AB$1004))
A32: =IF(Properties!A10="","",Properties!A10) | B32: =IF($A32="","",SUMPRODUCT(Bookings!$AA$5:$AA$1004*(($A32="All properties")+(Bookings!$D$5:$D$1004=$A32)>0)*(((((Bookings!$C$5:$C$1004+DATE($B$4+1,1,1)-ABS(Bookings!$C$5:$C$1004-DATE($B$4+1,1,1)))/2)-((Bookings!$B$5:$B$1004+DATE($B$4,1,1)+ABS(Bookings!$B$5:$B$1004-DATE($B$4,1,1)))/2))+ABS(((Bookings!$C$5:$C$1004+DATE($B$4+1,1,1)-ABS(Bookings!$C$5:$C$1004-DATE($B$4+1,1,1)))/2)-((Bookings!$B$5:$B$1004+DATE($B$4,1,1)+ABS(Bookings!$B$5:$B$1004-DATE($B$4,1,1)))/2)))/2))) | C32: =IF($A32="","",IF(K32=0,0,B32/K32)) | D32: =IF($A32="","",IF(B32=0,0,L32/B32)) | E32: =IF($A32="","",IF(K32=0,0,L32/K32)) | F32: =IF($A32="","",SUMPRODUCT(Bookings!$AA$5:$AA$1004*(($A32="All properties")+(Bookings!$D$5:$D$1004=$A32)>0)*(((((Bookings!$C$5:$C$1004+DATE($B$4+1,1,1)-ABS(Bookings!$C$5:$C$1004-DATE($B$4+1,1,1)))/2)-((Bookings!$B$5:$B$1004+DATE($B$4,1,1)+ABS(Bookings!$B$5:$B$1004-DATE($B$4,1,1)))/2))+ABS(((Bookings!$C$5:$C$1004+DATE($B$4+1,1,1)-ABS(Bookings!$C$5:$C$1004-DATE($B$4+1,1,1)))/2)-((Bookings!$B$5:$B$1004+DATE($B$4,1,1)+ABS(Bookings!$B$5:$B$1004-DATE($B$4,1,1)))/2)))/2)*Bookings!$AC$5:$AC$1004)) | G32: =IF($A32="","",SUMPRODUCT(Bookings!$AA$5:$AA$1004*(($A32="All properties")+(Bookings!$D$5:$D$1004=$A32)>0)*(((((Bookings!$C$5:$C$1004+DATE($B$4+1,1,1)-ABS(Bookings!$C$5:$C$1004-DATE($B$4+1,1,1)))/2)-((Bookings!$B$5:$B$1004+DATE($B$4,1,1)+ABS(Bookings!$B$5:$B$1004-DATE($B$4,1,1)))/2))+ABS(((Bookings!$C$5:$C$1004+DATE($B$4+1,1,1)-ABS(Bookings!$C$5:$C$1004-DATE($B$4+1,1,1)))/2)-((Bookings!$B$5:$B$1004+DATE($B$4,1,1)+ABS(Bookings!$B$5:$B$1004-DATE($B$4,1,1)))/2)))/2)*Bookings!$AD$5:$AD$1004)) | H32: =IF($A32="","",SUMIFS(Expenses!$F$5:$F$1004,Expenses!$A$5:$A$1004,">="&DATE($B$4,1,1),Expenses!$A$5:$A$1004,"<"&DATE($B$4+1,1,1),Expenses!$B$5:$B$1004,$A32)) | I32: =IF($A32="","",F32-G32-H32) | K32: =IF($A32="","",SUMPRODUCT((Properties!$A$5:$A$24<>"")*(($A32="All properties")+(Properties!$A$5:$A$24=$A32)>0)*(((DATE($B$4+1,1,1)-((Properties!$K$5:$K$24+DATE($B$4,1,1)+ABS(Properties!$K$5:$K$24-DATE($B$4,1,1)))/2))+ABS(DATE($B$4+1,1,1)-((Properties!$K$5:$K$24+DATE($B$4,1,1)+ABS(Properties!$K$5:$K$24-DATE($B$4,1,1)))/2)))/2))) | L32: =IF($A32="","",SUMPRODUCT(Bookings!$AA$5:$AA$1004*(($A32="All properties")+(Bookings!$D$5:$D$1004=$A32)>0)*(((((Bookings!$C$5:$C$1004+DATE($B$4+1,1,1)-ABS(Bookings!$C$5:$C$1004-DATE($B$4+1,1,1)))/2)-((Bookings!$B$5:$B$1004+DATE($B$4,1,1)+ABS(Bookings!$B$5:$B$1004-DATE($B$4,1,1)))/2))+ABS(((Bookings!$C$5:$C$1004+DATE($B$4+1,1,1)-ABS(Bookings!$C$5:$C$1004-DATE($B$4+1,1,1)))/2)-((Bookings!$B$5:$B$1004+DATE($B$4,1,1)+ABS(Bookings!$B$5:$B$1004-DATE($B$4,1,1)))/2)))/2)*Bookings!$AB$5:$AB$1004))
A33: =IF(Properties!A11="","",Properties!A11) | B33: =IF($A33="","",SUMPRODUCT(Bookings!$AA$5:$AA$1004*(($A33="All properties")+(Bookings!$D$5:$D$1004=$A33)>0)*(((((Bookings!$C$5:$C$1004+DATE($B$4+1,1,1)-ABS(Bookings!$C$5:$C$1004-DATE($B$4+1,1,1)))/2)-((Bookings!$B$5:$B$1004+DATE($B$4,1,1)+ABS(Bookings!$B$5:$B$1004-DATE($B$4,1,1)))/2))+ABS(((Bookings!$C$5:$C$1004+DATE($B$4+1,1,1)-ABS(Bookings!$C$5:$C$1004-DATE($B$4+1,1,1)))/2)-((Bookings!$B$5:$B$1004+DATE($B$4,1,1)+ABS(Bookings!$B$5:$B$1004-DATE($B$4,1,1)))/2)))/2))) | C33: =IF($A33="","",IF(K33=0,0,B33/K33)) | D33: =IF($A33="","",IF(B33=0,0,L33/B33)) | E33: =IF($A33="","",IF(K33=0,0,L33/K33)) | F33: =IF($A33="","",SUMPRODUCT(Bookings!$AA$5:$AA$1004*(($A33="All properties")+(Bookings!$D$5:$D$1004=$A33)>0)*(((((Bookings!$C$5:$C$1004+DATE($B$4+1,1,1)-ABS(Bookings!$C$5:$C$1004-DATE($B$4+1,1,1)))/2)-((Bookings!$B$5:$B$1004+DATE($B$4,1,1)+ABS(Bookings!$B$5:$B$1004-DATE($B$4,1,1)))/2))+ABS(((Bookings!$C$5:$C$1004+DATE($B$4+1,1,1)-ABS(Bookings!$C$5:$C$1004-DATE($B$4+1,1,1)))/2)-((Bookings!$B$5:$B$1004+DATE($B$4,1,1)+ABS(Bookings!$B$5:$B$1004-DATE($B$4,1,1)))/2)))/2)*Bookings!$AC$5:$AC$1004)) | G33: =IF($A33="","",SUMPRODUCT(Bookings!$AA$5:$AA$1004*(($A33="All properties")+(Bookings!$D$5:$D$1004=$A33)>0)*(((((Bookings!$C$5:$C$1004+DATE($B$4+1,1,1)-ABS(Bookings!$C$5:$C$1004-DATE($B$4+1,1,1)))/2)-((Bookings!$B$5:$B$1004+DATE($B$4,1,1)+ABS(Bookings!$B$5:$B$1004-DATE($B$4,1,1)))/2))+ABS(((Bookings!$C$5:$C$1004+DATE($B$4+1,1,1)-ABS(Bookings!$C$5:$C$1004-DATE($B$4+1,1,1)))/2)-((Bookings!$B$5:$B$1004+DATE($B$4,1,1)+ABS(Bookings!$B$5:$B$1004-DATE($B$4,1,1)))/2)))/2)*Bookings!$AD$5:$AD$1004)) | H33: =IF($A33="","",SUMIFS(Expenses!$F$5:$F$1004,Expenses!$A$5:$A$1004,">="&DATE($B$4,1,1),Expenses!$A$5:$A$1004,"<"&DATE($B$4+1,1,1),Expenses!$B$5:$B$1004,$A33)) | I33: =IF($A33="","",F33-G33-H33) | K33: =IF($A33="","",SUMPRODUCT((Properties!$A$5:$A$24<>"")*(($A33="All properties")+(Properties!$A$5:$A$24=$A33)>0)*(((DATE($B$4+1,1,1)-((Properties!$K$5:$K$24+DATE($B$4,1,1)+ABS(Properties!$K$5:$K$24-DATE($B$4,1,1)))/2))+ABS(DATE($B$4+1,1,1)-((Properties!$K$5:$K$24+DATE($B$4,1,1)+ABS(Properties!$K$5:$K$24-DATE($B$4,1,1)))/2)))/2))) | L33: =IF($A33="","",SUMPRODUCT(Bookings!$AA$5:$AA$1004*(($A33="All properties")+(Bookings!$D$5:$D$1004=$A33)>0)*(((((Bookings!$C$5:$C$1004+DATE($B$4+1,1,1)-ABS(Bookings!$C$5:$C$1004-DATE($B$4+1,1,1)))/2)-((Bookings!$B$5:$B$1004+DATE($B$4,1,1)+ABS(Bookings!$B$5:$B$1004-DATE($B$4,1,1)))/2))+ABS(((Bookings!$C$5:$C$1004+DATE($B$4+1,1,1)-ABS(Bookings!$C$5:$C$1004-DATE($B$4+1,1,1)))/2)-((Bookings!$B$5:$B$1004+DATE($B$4,1,1)+ABS(Bookings!$B$5:$B$1004-DATE($B$4,1,1)))/2)))/2)*Bookings!$AB$5:$AB$1004))
A34: =IF(Properties!A12="","",Properties!A12) | B34: =IF($A34="","",SUMPRODUCT(Bookings!$AA$5:$AA$1004*(($A34="All properties")+(Bookings!$D$5:$D$1004=$A34)>0)*(((((Bookings!$C$5:$C$1004+DATE($B$4+1,1,1)-ABS(Bookings!$C$5:$C$1004-DATE($B$4+1,1,1)))/2)-((Bookings!$B$5:$B$1004+DATE($B$4,1,1)+ABS(Bookings!$B$5:$B$1004-DATE($B$4,1,1)))/2))+ABS(((Bookings!$C$5:$C$1004+DATE($B$4+1,1,1)-ABS(Bookings!$C$5:$C$1004-DATE($B$4+1,1,1)))/2)-((Bookings!$B$5:$B$1004+DATE($B$4,1,1)+ABS(Bookings!$B$5:$B$1004-DATE($B$4,1,1)))/2)))/2))) | C34: =IF($A34="","",IF(K34=0,0,B34/K34)) | D34: =IF($A34="","",IF(B34=0,0,L34/B34)) | E34: =IF($A34="","",IF(K34=0,0,L34/K34)) | F34: =IF($A34="","",SUMPRODUCT(Bookings!$AA$5:$AA$1004*(($A34="All properties")+(Bookings!$D$5:$D$1004=$A34)>0)*(((((Bookings!$C$5:$C$1004+DATE($B$4+1,1,1)-ABS(Bookings!$C$5:$C$1004-DATE($B$4+1,1,1)))/2)-((Bookings!$B$5:$B$1004+DATE($B$4,1,1)+ABS(Bookings!$B$5:$B$1004-DATE($B$4,1,1)))/2))+ABS(((Bookings!$C$5:$C$1004+DATE($B$4+1,1,1)-ABS(Bookings!$C$5:$C$1004-DATE($B$4+1,1,1)))/2)-((Bookings!$B$5:$B$1004+DATE($B$4,1,1)+ABS(Bookings!$B$5:$B$1004-DATE($B$4,1,1)))/2)))/2)*Bookings!$AC$5:$AC$1004)) | G34: =IF($A34="","",SUMPRODUCT(Bookings!$AA$5:$AA$1004*(($A34="All properties")+(Bookings!$D$5:$D$1004=$A34)>0)*(((((Bookings!$C$5:$C$1004+DATE($B$4+1,1,1)-ABS(Bookings!$C$5:$C$1004-DATE($B$4+1,1,1)))/2)-((Bookings!$B$5:$B$1004+DATE($B$4,1,1)+ABS(Bookings!$B$5:$B$1004-DATE($B$4,1,1)))/2))+ABS(((Bookings!$C$5:$C$1004+DATE($B$4+1,1,1)-ABS(Bookings!$C$5:$C$1004-DATE($B$4+1,1,1)))/2)-((Bookings!$B$5:$B$1004+DATE($B$4,1,1)+ABS(Bookings!$B$5:$B$1004-DATE($B$4,1,1)))/2)))/2)*Bookings!$AD$5:$AD$1004)) | H34: =IF($A34="","",SUMIFS(Expenses!$F$5:$F$1004,Expenses!$A$5:$A$1004,">="&DATE($B$4,1,1),Expenses!$A$5:$A$1004,"<"&DATE($B$4+1,1,1),Expenses!$B$5:$B$1004,$A34)) | I34: =IF($A34="","",F34-G34-H34) | K34: =IF($A34="","",SUMPRODUCT((Properties!$A$5:$A$24<>"")*(($A34="All properties")+(Properties!$A$5:$A$24=$A34)>0)*(((DATE($B$4+1,1,1)-((Properties!$K$5:$K$24+DATE($B$4,1,1)+ABS(Properties!$K$5:$K$24-DATE($B$4,1,1)))/2))+ABS(DATE($B$4+1,1,1)-((Properties!$K$5:$K$24+DATE($B$4,1,1)+ABS(Properties!$K$5:$K$24-DATE($B$4,1,1)))/2)))/2))) | L34: =IF($A34="","",SUMPRODUCT(Bookings!$AA$5:$AA$1004*(($A34="All properties")+(Bookings!$D$5:$D$1004=$A34)>0)*(((((Bookings!$C$5:$C$1004+DATE($B$4+1,1,1)-ABS(Bookings!$C$5:$C$1004-DATE($B$4+1,1,1)))/2)-((Bookings!$B$5:$B$1004+DATE($B$4,1,1)+ABS(Bookings!$B$5:$B$1004-DATE($B$4,1,1)))/2))+ABS(((Bookings!$C$5:$C$1004+DATE($B$4+1,1,1)-ABS(Bookings!$C$5:$C$1004-DATE($B$4+1,1,1)))/2)-((Bookings!$B$5:$B$1004+DATE($B$4,1,1)+ABS(Bookings!$B$5:$B$1004-DATE($B$4,1,1)))/2)))/2)*Bookings!$AB$5:$AB$1004))
